Workbook

Sheet הערכת סיכונים
A1: Ci-Sec — סקר דוגמא גרסה 2 (גרסה 2) · רשת:
A2: מזהה בקרה | B2: משפחת בקרה | C2: קוד משפחה | D2: שם הבקרה | E2: תיאור הבקרה | F2: תחום ברשת | G2: תרחיש איום/סיכון | H2: הסתברות (1-4) | I2: השפעה (1-4) | J2: ציון סיכון | K2: רמת סיכון | L2: מבצע (R) | M2: פעולות מיטיגציה | N2: הסתברות שיורית | O2: השפעה שיורית | P2: סיכון שיורי | Q2: רמת סיכון שיורי | R2: סיכון נוכחי | S2: רמת סיכון נוכחי | T2: סטטוס | U2: תאריך יעד | V2: החלטת הנהלה | W2: בקרה לא רלוונטית | X2: סה"כ פעולות מיטיגציה | Y2: בוצעו | Z2: % ביצוע מיטיגציה | AA2: מורכבות טיפול | AB2: הערכה תקציבית | AC2: מטבע | AD2: ללא עלות | AE2: הערכת שעות עבודה | AF2: פירוט שעות עבודה
A3: GOV-01 | B3: ממשל וניהול סיכונים | C3: GOV | D3: אחריות ההנהלה להגנת הסייבר מעוגנת ומתוקשרת | E3: אחריות ההנהלה להגנת הסייבר מעוגנת ומתוקשרת | G3: היעדר עיגון אחריות ניהולית להגנת סייבר עלול לגרום לפערים בקבלת החלטות, חוסר הקצאת משאבים וכשל מערכתי בהגנה על הארגון מפני מתקפות סייבר | H3: 3 | I3: 3 | J3: =IF(OR(H3="",I3=""),"",H3*I3) -> 9 | K3: =IF(J3="","",IF(J3>=12,"קריטי",IF(J3>=8,"גבוה",IF(J3>=4,"בינוני","נמוך")))) -> גבוה | L3: מנהל מערכת | M3: 1. הגדרת ואישור מבנה ממשל סייבר ארגוני הכולל תפקידים ואחריות (NIST PM-1, PM-2) 2. עיגון אחריות ההנהלה בנהלים ובמסמכי מדיניות מאושרים (PM-13) 3. קיום סקירות הנהלה תקופתיות למצב הסייבר (PM-6) 4. מינוי נושא אחריות בכיר (Authorizing Official) לכל מערכת קריטית (CA-6) | N3: 1 | O3: 1 | P3: =IF(OR(N3="",O3=""),"",N3*O3) -> 1 | Q3: =IF(P3="","",IF(P3>=12,"קריטי",IF(P3>=8,"גבוה",IF(P3>=4,"בינוני","נמוך")))) -> נמוך | R3: =IF(J3="","",IF(X3>0,ROUND(J3-IF(T3="הושלם",1,Z3/100)*(J3-IF(P3="",J3,P3)),0),IF(T3="הושלם",IF(P3="",J3,P3),IF(T3="בתהליך",IF(P3="",J3,ROUND((J3+P3)/2,0)),J3)))) -> 5 | S3: =IF(R3="","",IF(R3>=12,"קריטי",IF(R3>=8,"גבוה",IF(R3>=4,"בינוני","נמוך")))) -> בינוני | T3: בתהליך | W3: לא | X3: 0 | Y3: 0 | Z3: =IF(X3=0,0,ROUND(Y3/X3*100,0)) -> 0 | AC3: ILS | AD3: לא
A4: GOV-02 | B4: ממשל וניהול סיכונים | C4: GOV | D4: מינוי ממונה הגנת סייבר (CISO) והגדרת סמכויותיו | E4: מינוי ממונה הגנת סייבר (CISO) והגדרת סמכויותיו | G4: היעדר ממונה הגנת סייבר (CISO) בעל סמכויות מוגדרות עלול להוביל לחוסר אחידות בניהול אבטחת המידע, היעדר דמות מובילה לטיפול באירועים ופערים בממשק עם ההנהלה והרגולטור | H4: 4 | I4: 4 | J4: =IF(OR(H4="",I4=""),"",H4*I4) -> 16 | K4: =IF(J4="","",IF(J4>=12,"קריטי",IF(J4>=8,"גבוה",IF(J4>=4,"בינוני","נמוך")))) -> קריטי | L4: מהנדס אבטחה | M4: 1. מינוי CISO/ממונה סייבר בכיר עם דיווח ישיר להנהלה (NIST PM-2) 2. הגדרת סמכויות, תחומי אחריות ומנדט פעולה בכתב (PM-1) 3. הקצאת צוות ומשאבים ייעודיים לממונה (PM-3) 4. שיבוץ CISO בפורום הנהלה ובוועדת סיכונים (PM-29) | N4: 2 | O4: 3 | P4: =IF(OR(N4="",O4=""),"",N4*O4) -> 6 | Q4: =IF(P4="","",IF(P4>=12,"קריטי",IF(P4>=8,"גבוה",IF(P4>=4,"בינוני","נמוך")))) -> בינוני | R4: =IF(J4="","",IF(X4>0,ROUND(J4-IF(T4="הושלם",1,Z4/100)*(J4-IF(P4="",J4,P4)),0),IF(T4="הושלם",IF(P4="",J4,P4),IF(T4="בתהליך",IF(P4="",J4,ROUND((J4+P4)/2,0)),J4)))) -> 16 | S4: =IF(R4="","",IF(R4>=12,"קריטי",IF(R4>=8,"גבוה",IF(R4>=4,"בינוני","נמוך")))) -> קריטי | T4: בתהליך | V4: הפחתת סיכון | W4: לא | X4: 3 | Y4: 0 | Z4: =IF(X4=0,0,ROUND(Y4/X4*100,0)) -> 0 | AC4: ILS | AD4: לא
A5: GOV-03 | B5: ממשל וניהול סיכונים | C5: GOV | D5: מדיניות הגנת סייבר ארגונית נקבעת, מאושרת ומופצת | E5: מדיניות הגנת סייבר ארגונית נקבעת, מאושרת ומופצת | G5: היעדר מדיניות סייבר מאושרת ומופצת עלול לגרום לפעולה ללא הנחיות אחידות, חשיפת הארגון לאיומים שאינם מכוסים ואי-עמידה בדרישות רגולציה | J5: =IF(OR(H5="",I5=""),"",H5*I5) | K5: =IF(J5="","",IF(J5>=12,"קריטי",IF(J5>=8,"גבוה",IF(J5>=4,"בינוני","נמוך")))) | L5: מהנדס רשת | M5: 1. גיבוש מדיניות אבטחת מידע ארגונית מקיפה (NIST PL-1) 2. אישור המדיניות ע"י ההנהלה הבכירה והפצה לכלל הגורמים (PL-1) 3. סקירה ועדכון המדיניות לפחות אחת לשנה (PL-1) 4. פיתוח נהלים תומכים לכל משפחת בקרות (PL-2, PM-1) | P5: =IF(OR(N5="",O5=""),"",N5*O5) | Q5: =IF(P5="","",IF(P5>=12,"קריטי",IF(P5>=8,"גבוה",IF(P5>=4,"בינוני","נמוך")))) | R5: =IF(J5="","",IF(X5>0,ROUND(J5-IF(T5="הושלם",1,Z5/100)*(J5-IF(P5="",J5,P5)),0),IF(T5="הושלם",IF(P5="",J5,P5),IF(T5="בתהליך",IF(P5="",J5,ROUND((J5+P5)/2,0)),J5)))) | S5: =IF(R5="","",IF(R5>=12,"קריטי",IF(R5>=8,"גבוה",IF(R5>=4,"בינוני","נמוך")))) | T5: לא התחיל | W5: לא | X5: 0 | Y5: 0 | Z5: =IF(X5=0,0,ROUND(Y5/X5*100,0)) -> 0 | AC5: ILS | AD5: לא
A6: GOV-04 | B6: ממשל וניהול סיכונים | C6: GOV | D6: תהליך ניהול סיכוני סייבר מתמשך (לא חד-פעמי) מוטמע | E6: תהליך ניהול סיכוני סייבר מתמשך (לא חד-פעמי) מוטמע | G6: היעדר תהליך ניהול סיכונים מתמשך עלול לגרום להצטברות סיכונים בלתי מזוהים, אי-זיהוי איומים חדשים ופגיעות שלא טופלו, ולחשיפה הולכת וגדלה של הארגון | H6: 4 | I6: 4 | J6: =IF(OR(H6="",I6=""),"",H6*I6) -> 16 | K6: =IF(J6="","",IF(J6>=12,"קריטי",IF(J6>=8,"גבוה",IF(J6>=4,"בינוני","נמוך")))) -> קריטי | L6: מנהל IR | M6: 1. הטמעת תהליך ניהול סיכונים מתמשך ומתועד (NIST RA-1, RA-3) 2. עדכון הערכת סיכונים לפחות אחת לשנה ובעקבות שינויים מהותיים (RA-3) 3. שילוב ניהול סיכוני סייבר במסגרת ניהול הסיכונים הארגוני (PM-9, PM-28) 4. שימוש במתודולוגיה מוכרת (NIST RMF) לניהול סיכונים (RA-1) | N6: 2 | O6: 3 | P6: =IF(OR(N6="",O6=""),"",N6*O6) -> 6 | Q6: =IF(P6="","",IF(P6>=12,"קריטי",IF(P6>=8,"גבוה",IF(P6>=4,"בינוני","נמוך")))) -> בינוני | R6: =IF(J6="","",IF(X6>0,ROUND(J6-IF(T6="הושלם",1,Z6/100)*(J6-IF(P6="",J6,P6)),0),IF(T6="הושלם",IF(P6="",J6,P6),IF(T6="בתהליך",IF(P6="",J6,ROUND((J6+P6)/2,0)),J6)))) -> 16 | S6: =IF(R6="","",IF(R6>=12,"קריטי",IF(R6>=8,"גבוה",IF(R6>=4,"בינוני","נמוך")))) -> קריטי | T6: לא התחיל | W6: לא | X6: 0 | Y6: 0 | Z6: =IF(X6=0,0,ROUND(Y6/X6*100,0)) -> 0 | AC6: ILS | AD6: לא
A7: GOV-05 | B7: ממשל וניהול סיכונים | C7: GOV | D7: תיאבון סיכון וסבילות סיכון מוגדרים ומאושרים בהנהלה | E7: תיאבון סיכון וסבילות סיכון מוגדרים ומאושרים בהנהלה | G7: היעדר הגדרת תיאבון וסבילות סיכון עלולים לגרום לקבלת החלטות שרירותיות בניהול סיכונים, השקעה בלתי מאוזנת במשאבי הגנה וחשיפה לסיכונים שההנהלה אינה מודעת לקבלתם | J7: =IF(OR(H7="",I7=""),"",H7*I7) | K7: =IF(J7="","",IF(J7>=12,"קריטי",IF(J7>=8,"גבוה",IF(J7>=4,"בינוני","נמוך")))) | L7: NetOps | M7: 1. הגדרת רמות תיאבון סיכון (Risk Appetite) ואישורן ע"י ההנהלה (NIST PM-9) 2. קביעת סבילות סיכון (Risk Tolerance) לכל מערכת קריטית (PM-9) 3. תיעוד והפצת מסגרת קבלת סיכונים לבעלי תפקידים רלוונטיים (PM-9) 4. סקירה שנתית והתאמת רמות הסיכון המקובלות (RA-3, PM-28) | P7: =IF(OR(N7="",O7=""),"",N7*O7) | Q7: =IF(P7="","",IF(P7>=12,"קריטי",IF(P7>=8,"גבוה",IF(P7>=4,"בינוני","נמוך")))) | R7: =IF(J7="","",IF(X7>0,ROUND(J7-IF(T7="הושלם",1,Z7/100)*(J7-IF(P7="",J7,P7)),0),IF(T7="הושלם",IF(P7="",J7,P7),IF(T7="בתהליך",IF(P7="",J7,ROUND((J7+P7)/2,0)),J7)))) | S7: =IF(R7="","",IF(R7>=12,"קריטי",IF(R7>=8,"גבוה",IF(R7>=4,"בינוני","נמוך")))) | T7: לא התחיל | W7: לא | X7: 0 | Y7: 0 | Z7: =IF(X7=0,0,ROUND(Y7/X7*100,0)) -> 0 | AC7: ILS | AD7: לא
A8: GOV-06 | B8: ממשל וניהול סיכונים | C8: GOV | D8: תקציב ומשאבים להגנת סייבר מוקצים בהתאם לפוטנציאל הנזק | E8: תקציב ומשאבים להגנת סייבר מוקצים בהתאם לפוטנציאל הנזק | G8: הקצאה לא מספקת של תקציב ומשאבים להגנת סייבר עלולה להותיר פערי הגנה קריטיים, להגביל יכולת תגובה לאירועים ולחשוף את הארגון לנזקים העולים על עלות ההשקעה בהגנה | J8: =IF(OR(H8="",I8=""),"",H8*I8) | K8: =IF(J8="","",IF(J8>=12,"קריטי",IF(J8>=8,"גבוה",IF(J8>=4,"בינוני","נמוך")))) | L8: מנהל IR | M8: 1. הקצאת תקציב ייעודי להגנת סייבר במסגרת התקציב הארגוני (NIST PM-3) 2. ביצוע ניתוח עלות-תועלת (BIA) לתעדוף השקעות אבטחה (PM-3) 3. הקצאת כוח אדם מקצועי ומיומן לתפקידי סייבר (PM-13, PM-15) 4. תכנון תקציב רב-שנתי הכולל הדרכות, כלים ותשתיות (PM-3) | P8: =IF(OR(N8="",O8=""),"",N8*O8) | Q8: =IF(P8="","",IF(P8>=12,"קריטי",IF(P8>=8,"גבוה",IF(P8>=4,"בינוני","נמוך")))) | R8: =IF(J8="","",IF(X8>0,ROUND(J8-IF(T8="הושלם",1,Z8/100)*(J8-IF(P8="",J8,P8)),0),IF(T8="הושלם",IF(P8="",J8,P8),IF(T8="בתהליך",IF(P8="",J8,ROUND((J8+P8)/2,0)),J8)))) | S8: =IF(R8="","",IF(R8>=12,"קריטי",IF(R8>=8,"גבוה",IF(R8>=4,"בינוני","נמוך")))) | T8: לא התחיל | W8: לא | X8: 0 | Y8: 0 | Z8: =IF(X8=0,0,ROUND(Y8/X8*100,0)) -> 0 | AC8: ILS | AD8: לא
A9: GOV-07 | B9: ממשל וניהול סיכונים | C9: GOV | D9: תוכנית הגנת סייבר רב-שנתית נגזרת מהאסטרטגיה ומנוטרת | E9: תוכנית הגנת סייבר רב-שנתית נגזרת מהאסטרטגיה ומנוטרת | G9: היעדר תוכנית הגנת סייבר רב-שנתית עלולה לגרום לפעילות אד-הוק, חוסר התאמה בין ההגנה לאסטרטגיה העסקית ולפערים מצטברים ביכולות ההגנה לאורך זמן | J9: =IF(OR(H9="",I9=""),"",H9*I9) | K9: =IF(J9="","",IF(J9>=12,"קריטי",IF(J9>=8,"גבוה",IF(J9>=4,"בינוני","נמוך")))) | L9: מנהל מערכת | M9: 1. גיבוש תוכנית הגנת סייבר רב-שנתית מבוססת אסטרטגיה (NIST PM-1) 2. הגדרת אבני דרך, מדדי הצלחה ולוחות זמנים (PM-4) 3. ניטור התקדמות יישום התוכנית ודיווח תקופתי להנהלה (PM-6) 4. עדכון התוכנית בהתאם לשינויים באיומים ובסביבה העסקית (PM-4) | P9: =IF(OR(N9="",O9=""),"",N9*O9) | Q9: =IF(P9="","",IF(P9>=12,"קריטי",IF(P9>=8,"גבוה",IF(P9>=4,"בינוני","נמוך")))) | R9: =IF(J9="","",IF(X9>0,ROUND(J9-IF(T9="הושלם",1,Z9/100)*(J9-IF(P9="",J9,P9)),0),IF(T9="הושלם",IF(P9="",J9,P9),IF(T9="בתהליך",IF(P9="",J9,ROUND((J9+P9)/2,0)),J9)))) | S9: =IF(R9="","",IF(R9>=12,"קריטי",IF(R9>=8,"גבוה",IF(R9>=4,"בינוני","נמוך")))) | T9: לא התחיל | W9: לא | X9: 0 | Y9: 0 | Z9: =IF(X9=0,0,ROUND(Y9/X9*100,0)) -> 0 | AC9: ILS | AD9: לא
A10: GOV-08 | B10: ממשל וניהול סיכונים | C10: GOV | D10: עמידה בדרישות רגולציה וחקיקה רלוונטיות לסייבר | E10: עמידה בדרישות רגולציה וחקיקה רלוונטיות לסייבר | G10: אי-עמידה בדרישות רגולציה וחקיקה עלולה לחשוף את הארגון לקנסות, תביעות, סנקציות רגולטוריות ופגיעה במוניטין, בנוסף לחשיפת מידע רגיש | J10: =IF(OR(H10="",I10=""),"",H10*I10) | K10: =IF(J10="","",IF(J10>=12,"קריטי",IF(J10>=8,"גבוה",IF(J10>=4,"בינוני","נמוך")))) | L10: אנליסט SOC | M10: 1. מיפוי דרישות רגולציה וחקיקה רלוונטיות לסייבר (NIST PM-8, PM-10) 2. ביצוע הערכת ציות (compliance assessment) תקופתית (CA-2, CA-7) 3. הקמת תהליך מעקב אחר שינויי רגולציה ועדכון הבקרות בהתאם (PM-8) 4. תיעוד פערי ציות ותוכנית סגירתם (CA-5, PM-10) | P10: =IF(OR(N10="",O10=""),"",N10*O10) | Q10: =IF(P10="","",IF(P10>=12,"קריטי",IF(P10>=8,"גבוה",IF(P10>=4,"בינוני","נמוך")))) | R10: =IF(J10="","",IF(X10>0,ROUND(J10-IF(T10="הושלם",1,Z10/100)*(J10-IF(P10="",J10,P10)),0),IF(T10="הושלם",IF(P10="",J10,P10),IF(T10="בתהליך",IF(P10="",J10,ROUND((J10+P10)/2,0)),J10)))) | S10: =IF(R10="","",IF(R10>=12,"קריטי",IF(R10>=8,"גבוה",IF(R10>=4,"בינוני","נמוך")))) | T10: לא התחיל | W10: לא | X10: 0 | Y10: 0 | Z10: =IF(X10=0,0,ROUND(Y10/X10*100,0)) -> 0 | AC10: ILS | AD10: לא
A11: GOV-09 | B11: ממשל וניהול סיכונים | C11: GOV | D11: מדדי בקרה ודיווח תקופתי להנהלה על מצב הסיכון | E11: מדדי בקרה ודיווח תקופתי להנהלה על מצב הסיכון | G11: היעדר מדדי בקרה ודיווח תקופתי עלולים לגרום לחוסר מודעות של ההנהלה למצב הסיכון בפועל, עיכוב בקבלת החלטות ואי-זיהוי מגמות שליליות בהגנת הסייבר | J11: =IF(OR(H11="",I11=""),"",H11*I11) | K11: =IF(J11="","",IF(J11>=12,"קריטי",IF(J11>=8,"גבוה",IF(J11>=4,"בינוני","נמוך")))) | L11: אנליסט SOC | M11: 1. הגדרת KPIs ומדדי אפקטיביות להגנת סייבר (NIST PM-6, PM-14) 2. הפקת דוחות תקופתיים להנהלה על מצב הסיכון (PM-6) 3. שימוש בדשבורד ניהולי עם מדדי בקרה מרכזיים (PM-14) 4. ביצוע סקירות רבעוניות של מגמות סיכון ואירועים (CA-7, PM-6) | P11: =IF(OR(N11="",O11=""),"",N11*O11) | Q11: =IF(P11="","",IF(P11>=12,"קריטי",IF(P11>=8,"גבוה",IF(P11>=4,"בינוני","נמוך")))) | R11: =IF(J11="","",IF(X11>0,ROUND(J11-IF(T11="הושלם",1,Z11/100)*(J11-IF(P11="",J11,P11)),0),IF(T11="הושלם",IF(P11="",J11,P11),IF(T11="בתהליך",IF(P11="",J11,ROUND((J11+P11)/2,0)),J11)))) | S11: =IF(R11="","",IF(R11>=12,"קריטי",IF(R11>=8,"גבוה",IF(R11>=4,"בינוני","נמוך")))) | T11: לא התחיל | W11: לא | X11: 0 | Y11: 0 | Z11: =IF(X11=0,0,ROUND(Y11/X11*100,0)) -> 0 | AC11: ILS | AD11: לא
A12: GOV-10 | B12: ממשל וניהול סיכונים | C12: GOV | D12: מבדקי חוסן ובקרות עצמיות תקופתיים מבוצעים | E12: מבדקי חוסן ובקרות עצמיות תקופתיים מבוצעים | G12: אי-ביצוע מבדקי חוסן ובקרות עצמיות עלול להותיר פגיעויות לא מזוהות, לייצר תחושת ביטחון מוטעית ולאפשר לתוקפים לנצל חולשות שלא נבדקו | J12: =IF(OR(H12="",I12=""),"",H12*I12) | K12: =IF(J12="","",IF(J12>=12,"קריטי",IF(J12>=8,"גבוה",IF(J12>=4,"בינוני","נמוך")))) | L12: מנהל IR | M12: 1. ביצוע מבדקי חדירה (penetration testing) תקופתיים (NIST CA-8) 2. ביצוע הערכות בקרה פנימיות לפחות אחת לשנה (CA-2) 3. ביצוע סקירות תצורה ובקרות עצמיות (CA-7) 4. תיעוד ומעקב אחר ממצאים עד לסגירתם (CA-5, POA&M) | P12: =IF(OR(N12="",O12=""),"",N12*O12) | Q12: =IF(P12="","",IF(P12>=12,"קריטי",IF(P12>=8,"גבוה",IF(P12>=4,"בינוני","נמוך")))) | R12: =IF(J12="","",IF(X12>0,ROUND(J12-IF(T12="הושלם",1,Z12/100)*(J12-IF(P12="",J12,P12)),0),IF(T12="הושלם",IF(P12="",J12,P12),IF(T12="בתהליך",IF(P12="",J12,ROUND((J12+P12)/2,0)),J12)))) | S12: =IF(R12="","",IF(R12>=12,"קריטי",IF(R12>=8,"גבוה",IF(R12>=4,"בינוני","נמוך")))) | T12: לא התחיל | W12: לא | X12: 0 | Y12: 0 | Z12: =IF(X12=0,0,ROUND(Y12/X12*100,0)) -> 0 | AC12: ILS | AD12: לא
A13: IDN-01 | B13: זיהוי ומיפוי נכסים | C13: IDN | D13: מיפוי ותחזוקת מצאי נכסי מידע (חומרה, תוכנה, שירותים) | E13: מיפוי ותחזוקת מצאי נכסי מידע (חומרה, תוכנה, שירותים) | G13: היעדר מצאי נכסי מידע מעודכן עלול לגרום להגנה חלקית בלבד, נכסים לא מוגנים המהווים וקטור תקיפה, וחוסר יכולת להעריך את היקף הנזק באירוע סייבר | J13: =IF(OR(H13="",I13=""),"",H13*I13) | K13: =IF(J13="","",IF(J13>=12,"קריטי",IF(J13>=8,"גבוה",IF(J13>=4,"בינוני","נמוך")))) | L13: מנהל מערכת | M13: 1. הקמת מצאי נכסים (Asset Inventory) מלא ומעודכן — חומרה, תוכנה ושירותים (NIST CM-8) 2. שימוש בכלי סריקה אוטומטיים לגילוי נכסים ברשת (CM-8(2)) 3. עדכון מצאי נכסים בכל שינוי ולפחות רבעונית (CM-8(1)) 4. שיוך בעלים (owner) לכל נכס מידע (CM-8(5), PM-5) | P13: =IF(OR(N13="",O13=""),"",N13*O13) | Q13: =IF(P13="","",IF(P13>=12,"קריטי",IF(P13>=8,"גבוה",IF(P13>=4,"בינוני","נמוך")))) | R13: =IF(J13="","",IF(X13>0,ROUND(J13-IF(T13="הושלם",1,Z13/100)*(J13-IF(P13="",J13,P13)),0),IF(T13="הושלם",IF(P13="",J13,P13),IF(T13="בתהליך",IF(P13="",J13,ROUND((J13+P13)/2,0)),J13)))) | S13: =IF(R13="","",IF(R13>=12,"קריטי",IF(R13>=8,"גבוה",IF(R13>=4,"בינוני","נמוך")))) | T13: לא התחיל | W13: לא | X13: 0 | Y13: 0 | Z13: =IF(X13=0,0,ROUND(Y13/X13*100,0)) -> 0 | AC13: ILS | AD13: לא
A14: IDN-02 | B14: זיהוי ומיפוי נכסים | C14: IDN | D14: סיווג נכסים לפי קריטיות לתפקוד הארגון | E14: סיווג נכסים לפי קריטיות לתפקוד הארגון | G14: היעדר סיווג נכסים לפי קריטיות עלול להוביל להקצאת משאבי הגנה שגויה, הגנה שווה על נכסים בעלי חשיבות שונה וחשיפת נכסים קריטיים ללא הגנה מספקת | J14: =IF(OR(H14="",I14=""),"",H14*I14) | K14: =IF(J14="","",IF(J14>=12,"קריטי",IF(J14>=8,"גבוה",IF(J14>=4,"בינוני","נמוך")))) | L14: GRC | M14: 1. סיווג נכסים לפי רמת קריטיות וחשיבות לתפקוד הארגון (NIST RA-2) 2. ביצוע ניתוח השפעה עסקית (BIA) לנכסים קריטיים (RA-2, CP-2) 3. הגדרת רמות סיווג (גבוה/בינוני/נמוך) לנכסים (RA-2) 4. תיעוד ועדכון סיווג נכסים בעקבות שינויים (RA-2, CM-8) | P14: =IF(OR(N14="",O14=""),"",N14*O14) | Q14: =IF(P14="","",IF(P14>=12,"קריטי",IF(P14>=8,"גבוה",IF(P14>=4,"בינוני","נמוך")))) | R14: =IF(J14="","",IF(X14>0,ROUND(J14-IF(T14="הושלם",1,Z14/100)*(J14-IF(P14="",J14,P14)),0),IF(T14="הושלם",IF(P14="",J14,P14),IF(T14="בתהליך",IF(P14="",J14,ROUND((J14+P14)/2,0)),J14)))) | S14: =IF(R14="","",IF(R14>=12,"קריטי",IF(R14>=8,"גבוה",IF(R14>=4,"בינוני","נמוך")))) | T14: לא התחיל | W14: לא | X14: 0 | Y14: 0 | Z14: =IF(X14=0,0,ROUND(Y14/X14*100,0)) -> 0 | AC14: ILS | AD14: לא
A15: IDN-03 | B15: זיהוי ומיפוי נכסים | C15: IDN | D15: מיפוי תהליכים עסקיים קריטיים ותלויותיהם | E15: מיפוי תהליכים עסקיים קריטיים ותלויותיהם | G15: היעדר מיפוי תהליכים עסקיים קריטיים ותלויותיהם עלול לגרום לאי-זיהוי נקודות כשל בודדות (SPOF), כשל בתעדוף התאוששות ופגיעה בהמשכיות העסקית | J15: =IF(OR(H15="",I15=""),"",H15*I15) | K15: =IF(J15="","",IF(J15>=12,"קריטי",IF(J15>=8,"גבוה",IF(J15>=4,"בינוני","נמוך")))) | L15: ארכיטקט | M15: 1. מיפוי תהליכים עסקיים קריטיים וזיהוי תלויות טכנולוגיות (NIST PM-11, CP-2) 2. ביצוע ניתוח השפעה עסקית (BIA) לתהליכים מרכזיים (CP-2) 3. זיהוי נקודות כשל בודדות (SPOF) בתהליכים (CP-2, SA-14) 4. תיעוד מפת תלויות ועדכונה תקופתי (PM-11, PL-2) | P15: =IF(OR(N15="",O15=""),"",N15*O15) | Q15: =IF(P15="","",IF(P15>=12,"קריטי",IF(P15>=8,"גבוה",IF(P15>=4,"בינוני","נמוך")))) | R15: =IF(J15="","",IF(X15>0,ROUND(J15-IF(T15="הושלם",1,Z15/100)*(J15-IF(P15="",J15,P15)),0),IF(T15="הושלם",IF(P15="",J15,P15),IF(T15="בתהליך",IF(P15="",J15,ROUND((J15+P15)/2,0)),J15)))) | S15: =IF(R15="","",IF(R15>=12,"קריטי",IF(R15>=8,"גבוה",IF(R15>=4,"בינוני","נמוך")))) | T15: לא התחיל | W15: לא | X15: 0 | Y15: 0 | Z15: =IF(X15=0,0,ROUND(Y15/X15*100,0)) -> 0 | AC15: ILS | AD15: לא
A16: IDN-04 | B16: זיהוי ומיפוי נכסים | C16: IDN | D16: מיפוי זרימות מידע, ממשקים ונקודות חיבור לאינטרנט | E16: מיפוי זרימות מידע, ממשקים ונקודות חיבור לאינטרנט | G16: היעדר מיפוי זרימות מידע, ממשקים ונקודות חיבור לאינטרנט עלול לחשוף נתיבי תקיפה בלתי מנוטרים, לאפשר דלף מידע דרך ממשקים לא מוגנים ולהקשות על בלימת אירוע | J16: =IF(OR(H16="",I16=""),"",H16*I16) | K16: =IF(J16="","",IF(J16>=12,"קריטי",IF(J16>=8,"גבוה",IF(J16>=4,"בינוני","נמוך")))) | L16: מנהל מערכת | M16: 1. מיפוי מלא של זרימות מידע בין מערכות, ממשקים ונקודות חיבור (NIST AC-4, PL-2) 2. תיעוד כל נקודות החיבור לאינטרנט ולרשתות חיצוניות (CA-3, SA-9) 3. סקירה ואישור של כל ממשק חדש לפני הפעלתו (CA-3) 4. ניטור זרימות מידע חריגות ועדכון מפת הממשקים (AC-4, CM-8) | P16: =IF(OR(N16="",O16=""),"",N16*O16) | Q16: =IF(P16="","",IF(P16>=12,"קריטי",IF(P16>=8,"גבוה",IF(P16>=4,"בינוני","נמוך")))) | R16: =IF(J16="","",IF(X16>0,ROUND(J16-IF(T16="הושלם",1,Z16/100)*(J16-IF(P16="",J16,P16)),0),IF(T16="הושלם",IF(P16="",J16,P16),IF(T16="בתהליך",IF(P16="",J16,ROUND((J16+P16)/2,0)),J16)))) | S16: =IF(R16="","",IF(R16>=12,"קריטי",IF(R16>=8,"גבוה",IF(R16>=4,"בינוני","נמוך")))) | T16: לא התחיל | W16: לא | X16: 0 | Y16: 0 | Z16: =IF(X16=0,0,ROUND(Y16/X16*100,0)) -> 0 | AC16: ILS | AD16: לא
A17: IDN-05 | B17: זיהוי ומיפוי נכסים | C17: IDN | D17: מיפוי משתמשים, הרשאות ובעלי גישה לנכסים | E17: מיפוי משתמשים, הרשאות ובעלי גישה לנכסים | G17: היעדר מיפוי משתמשים והרשאות עלול לאפשר גישה בלתי מורשית לנכסים, הצטברות הרשאות עודפות (privilege creep) וחוסר יכולת לזהות שימוש לרעה בחשבונות | J17: =IF(OR(H17="",I17=""),"",H17*I17) | K17: =IF(J17="","",IF(J17>=12,"קריטי",IF(J17>=8,"גבוה",IF(J17>=4,"בינוני","נמוך")))) | L17: מנהל מערכת | M17: 1. מיפוי כלל המשתמשים, תפקידיהם והרשאותיהם בכל מערכת (NIST AC-2) 2. ביצוע סקירת הרשאות (access review) תקופתית (AC-2(13)) 3. זיהוי וטיפול בהרשאות עודפות ובחשבונות יתומים (AC-2(3)) 4. תיעוד מטריצת הרשאות ובעלי גישה לנכסים קריטיים (AC-2, AC-6) | P17: =IF(OR(N17="",O17=""),"",N17*O17) | Q17: =IF(P17="","",IF(P17>=12,"קריטי",IF(P17>=8,"גבוה",IF(P17>=4,"בינוני","נמוך")))) | R17: =IF(J17="","",IF(X17>0,ROUND(J17-IF(T17="הושלם",1,Z17/100)*(J17-IF(P17="",J17,P17)),0),IF(T17="הושלם",IF(P17="",J17,P17),IF(T17="בתהליך",IF(P17="",J17,ROUND((J17+P17)/2,0)),J17)))) | S17: =IF(R17="","",IF(R17>=12,"קריטי",IF(R17>=8,"גבוה",IF(R17>=4,"בינוני","נמוך")))) | T17: לא התחיל | W17: לא | X17: 0 | Y17: 0 | Z17: =IF(X17=0,0,ROUND(Y17/X17*100,0)) -> 0 | AC17: ILS | AD17: לא
A18: IDN-06 | B18: זיהוי ומיפוי נכסים | C18: IDN | D18: זיהוי איום הייחוס (תוקף רלוונטי) ותרחישי תקיפה | E18: זיהוי איום הייחוס (תוקף רלוונטי) ותרחישי תקיפה | G18: היעדר זיהוי איום ייחוס ותרחישי תקיפה עלול לגרום להגנה שאינה מותאמת לאיומים הרלוונטיים, חוסר מוכנות לתרחישי תקיפה סבירים ובזבוז משאבים על איומים לא רלוונטיים | J18: =IF(OR(H18="",I18=""),"",H18*I18) | K18: =IF(J18="","",IF(J18>=12,"קריטי",IF(J18>=8,"גבוה",IF(J18>=4,"בינוני","נמוך")))) | L18: מנהל מערכת | M18: 1. ביצוע ניתוח איום ייחוס (threat modeling) רלוונטי לארגון (NIST RA-3, RA-5) 2. מיפוי תוקפים רלוונטיים, יכולותיהם ומוטיבציות (RA-3(1)) 3. בניית תרחישי תקיפה מבוססי MITRE ATT&CK (RA-3) 4. עדכון פרופיל האיום בהתאם למודיעין סייבר שוטף (PM-16, RA-3) | P18: =IF(OR(N18="",O18=""),"",N18*O18) | Q18: =IF(P18="","",IF(P18>=12,"קריטי",IF(P18>=8,"גבוה",IF(P18>=4,"בינוני","נמוך")))) | R18: =IF(J18="","",IF(X18>0,ROUND(J18-IF(T18="הושלם",1,Z18/100)*(J18-IF(P18="",J18,P18)),0),IF(T18="הושלם",IF(P18="",J18,P18),IF(T18="בתהליך",IF(P18="",J18,ROUND((J18+P18)/2,0)),J18)))) | S18: =IF(R18="","",IF(R18>=12,"קריטי",IF(R18>=8,"גבוה",IF(R18>=4,"בינוני","נמוך")))) | T18: לא התחיל | W18: לא | X18: 0 | Y18: 0 | Z18: =IF(X18=0,0,ROUND(Y18/X18*100,0)) -> 0 | AC18: ILS | AD18: לא
A19: IDN-07 | B19: זיהוי ומיפוי נכסים | C19: IDN | D19: מיפוי פערי הגנה מול תרחישי התקיפה הרלוונטיים | E19: מיפוי פערי הגנה מול תרחישי התקיפה הרלוונטיים | G19: היעדר מיפוי פערי הגנה מול תרחישי תקיפה עלול להותיר נתיבי תקיפה פתוחים, חשיפה לא מזוהה ביכולות ההגנה וכשל במענה לתקיפות ידועות | J19: =IF(OR(H19="",I19=""),"",H19*I19) | K19: =IF(J19="","",IF(J19>=12,"קריטי",IF(J19>=8,"גבוה",IF(J19>=4,"בינוני","נמוך")))) | L19: GRC | M19: 1. ביצוע ניתוח פערים (gap analysis) בין תרחישי תקיפה ליכולות ההגנה (NIST CA-2, RA-3) 2. מיפוי בקרות חסרות או חלקיות מול MITRE ATT&CK (CA-2) 3. תעדוף פערים לפי רמת סיכון וסבירות (RA-3, PM-9) 4. בניית תוכנית פעולה (POA&M) לסגירת פערים (CA-5) | P19: =IF(OR(N19="",O19=""),"",N19*O19) | Q19: =IF(P19="","",IF(P19>=12,"קריטי",IF(P19>=8,"גבוה",IF(P19>=4,"בינוני","נמוך")))) | R19: =IF(J19="","",IF(X19>0,ROUND(J19-IF(T19="הושלם",1,Z19/100)*(J19-IF(P19="",J19,P19)),0),IF(T19="הושלם",IF(P19="",J19,P19),IF(T19="בתהליך",IF(P19="",J19,ROUND((J19+P19)/2,0)),J19)))) | S19: =IF(R19="","",IF(R19>=12,"קריטי",IF(R19>=8,"גבוה",IF(R19>=4,"בינוני","נמוך")))) | T19: לא התחיל | W19: לא | X19: 0 | Y19: 0 | Z19: =IF(X19=0,0,ROUND(Y19/X19*100,0)) -> 0 | AC19: ILS | AD19: לא
A20: PRA-01 | B20: הגנה — גישה וזהות | C20: PRA | D20: ניהול זהויות והרשאות לאורך מחזור החיים (JML) | E20: ניהול זהויות והרשאות לאורך מחזור החיים (JML) | G20: היעדר ניהול זהויות והרשאות לאורך מחזור החיים עלול לאפשר חשבונות יתומים, הרשאות עודפות לעובדים שעזבו וניצול חשבונות לא מנוהלים כווקטור תקיפה | H20: 2 | I20: 2 | J20: =IF(OR(H20="",I20=""),"",H20*I20) -> 4 | K20: =IF(J20="","",IF(J20>=12,"קריטי",IF(J20>=8,"גבוה",IF(J20>=4,"בינוני","נמוך")))) -> בינוני | L20: מהנדס אבטחה | M20: 1. הטמעת תהליך Joiner-Mover-Leaver לניהול מחזור חיי זהויות (NIST AC-2) 2. ביטול אוטומטי של חשבונות בעת עזיבה/העברת תפקיד (AC-2(2), AC-2(3)) 3. שימוש במערכת IAM מרכזית לניהול זהויות (IA-4, IA-5) 4. סקירה תקופתית של חשבונות פעילים וביטול חשבונות לא פעילים (AC-2(3), AC-2(13)) | N20: 2 | O20: 1 | P20: =IF(OR(N20="",O20=""),"",N20*O20) -> 2 | Q20: =IF(P20="","",IF(P20>=12,"קריטי",IF(P20>=8,"גבוה",IF(P20>=4,"בינוני","נמוך")))) -> נמוך | R20: =IF(J20="","",IF(X20>0,ROUND(J20-IF(T20="הושלם",1,Z20/100)*(J20-IF(P20="",J20,P20)),0),IF(T20="הושלם",IF(P20="",J20,P20),IF(T20="בתהליך",IF(P20="",J20,ROUND((J20+P20)/2,0)),J20)))) -> 4 | S20: =IF(R20="","",IF(R20>=12,"קריטי",IF(R20>=8,"גבוה",IF(R20>=4,"בינוני","נמוך")))) -> בינוני | T20: לא התחיל | W20: לא | X20: 0 | Y20: 0 | Z20: =IF(X20=0,0,ROUND(Y20/X20*100,0)) -> 0 | AA20: קל | AC20: ILS | AD20: לא
A21: PRA-02 | B21: הגנה — גישה וזהות | C21: PRA | D21: אכיפת עקרון הרשאות מינימום (least privilege) | E21: אכיפת עקרון הרשאות מינימום (least privilege) | G21: אי-אכיפת עקרון הרשאות מינימום עלולה לאפשר לתוקף שפרץ לחשבון אחד להגיע למשאבים קריטיים, להרחיב נזק מאירוע בודד ולהקשות על בלימת מתקפה | H21: 4 | I21: 4 | J21: =IF(OR(H21="",I21=""),"",H21*I21) -> 16 | K21: =IF(J21="","",IF(J21>=12,"קריטי",IF(J21>=8,"גבוה",IF(J21>=4,"בינוני","נמוך")))) -> קריטי | L21: מנהל IR | M21: 1. יישום עקרון least privilege בכל מערכת ואפליקציה (NIST AC-6) 2. הגבלת גישה לפי תפקיד (RBAC) עם הרשאות מינימליות (AC-6(1)) 3. ביטול הרשאות ברירת מחדל עודפות (AC-6(2)) 4. סקירת הרשאות תקופתית וצמצום הרשאות עודפות (AC-6(7), AC-2(13)) | N21: 2 | O21: 1 | P21: =IF(OR(N21="",O21=""),"",N21*O21) -> 2 | Q21: =IF(P21="","",IF(P21>=12,"קריטי",IF(P21>=8,"גבוה",IF(P21>=4,"בינוני","נמוך")))) -> נמוך | R21: =IF(J21="","",IF(X21>0,ROUND(J21-IF(T21="הושלם",1,Z21/100)*(J21-IF(P21="",J21,P21)),0),IF(T21="הושלם",IF(P21="",J21,P21),IF(T21="בתהליך",IF(P21="",J21,ROUND((J21+P21)/2,0)),J21)))) -> 2 | S21: =IF(R21="","",IF(R21>=12,"קריטי",IF(R21>=8,"גבוה",IF(R21>=4,"בינוני","נמוך")))) -> נמוך | T21: לא התחיל | V21: הפחתת סיכון | W21: לא | X21: 3 | Y21: 3 | Z21: =IF(X21=0,0,ROUND(Y21/X21*100,0)) -> 100 | AA21: בינוני | AC21: ILS | AD21: לא | AE21: 24
A22: PRA-03 | B22: הגנה — גישה וזהות | C22: PRA | D22: אימות רב-גורמי (MFA) לגישות מרחוק ולחשבונות רגישים | E22: אימות רב-גורמי (MFA) לגישות מרחוק ולחשבונות רגישים | G22: היעדר אימות רב-גורמי (MFA) עלול לאפשר גישה למערכות רגישות באמצעות סיסמה גנובה בלבד, פריצה דרך תקיפת פישינג ואובדן שליטה על חשבונות בעלי הרשאה גבוהה | J22: =IF(OR(H22="",I22=""),"",H22*I22) | K22: =IF(J22="","",IF(J22>=12,"קריטי",IF(J22>=8,"גבוה",IF(J22>=4,"בינוני","נמוך")))) | L22: מהנדס רשת | M22: 1. הטמעת MFA לכל גישה מרחוק ולמערכות קריטיות (NIST IA-2(1), IA-2(2)) 2. חסימת גישת VPN וגישה מרחוק ללא MFA (IA-2(6)) 3. אכיפת MFA על חשבונות בעלי הרשאה גבוהה (IA-2(1)) 4. שימוש בגורמי אימות עמידים (FIDO2/authenticator app) ולא SMS (IA-2(6)) | P22: =IF(OR(N22="",O22=""),"",N22*O22) | Q22: =IF(P22="","",IF(P22>=12,"קריטי",IF(P22>=8,"גבוה",IF(P22>=4,"בינוני","נמוך")))) | R22: =IF(J22="","",IF(X22>0,ROUND(J22-IF(T22="הושלם",1,Z22/100)*(J22-IF(P22="",J22,P22)),0),IF(T22="הושלם",IF(P22="",J22,P22),IF(T22="בתהליך",IF(P22="",J22,ROUND((J22+P22)/2,0)),J22)))) | S22: =IF(R22="","",IF(R22>=12,"קריטי",IF(R22>=8,"גבוה",IF(R22>=4,"בינוני","נמוך")))) | T22: לא התחיל | W22: כן | X22: 0 | Y22: 0 | Z22: =IF(X22=0,0,ROUND(Y22/X22*100,0)) -> 0 | AC22: ILS | AD22: לא | AE22: 48
A23: PRA-04 | B23: הגנה — גישה וזהות | C23: PRA | D23: ניהול והגנה על חשבונות הרשאה גבוהה (PAM) | E23: ניהול והגנה על חשבונות הרשאה גבוהה (PAM) | G23: היעדר ניהול חשבונות הרשאה גבוהה (PAM) עלול לאפשר שימוש לרעה בהרשאות אדמין, היעדר מעקב על פעולות מיוחסות ותנועה רוחבית חופשית של תוקף ברשת | H23: 3 | I23: 2 | J23: =IF(OR(H23="",I23=""),"",H23*I23) -> 6 | K23: =IF(J23="","",IF(J23>=12,"קריטי",IF(J23>=8,"גבוה",IF(J23>=4,"בינוני","נמוך")))) -> בינוני | L23: אנליסט SOC | M23: 1. הטמעת פתרון PAM לניהול חשבונות הרשאה גבוהה (NIST AC-2(7), AC-6(5)) 2. אחסון סיסמאות אדמין בכספת סיסמאות מוצפנת (IA-5(7)) 3. הקלטת ומעקב אחר כל session של חשבון מיוחס (AC-2(4), AU-12) 4. הגבלת שימוש בחשבונות אדמין למשימות ניהוליות בלבד (AC-6(5)) | N23: 2 | O23: 1 | P23: =IF(OR(N23="",O23=""),"",N23*O23) -> 2 | Q23: =IF(P23="","",IF(P23>=12,"קריטי",IF(P23>=8,"גבוה",IF(P23>=4,"בינוני","נמוך")))) -> נמוך | R23: =IF(J23="","",IF(X23>0,ROUND(J23-IF(T23="הושלם",1,Z23/100)*(J23-IF(P23="",J23,P23)),0),IF(T23="הושלם",IF(P23="",J23,P23),IF(T23="בתהליך",IF(P23="",J23,ROUND((J23+P23)/2,0)),J23)))) -> 6 | S23: =IF(R23="","",IF(R23>=12,"קריטי",IF(R23>=8,"גבוה",IF(R23>=4,"בינוני","נמוך")))) -> בינוני | T23: לא התחיל | V23: הפחתת סיכון | W23: לא | X23: 0 | Y23: 0 | Z23: =IF(X23=0,0,ROUND(Y23/X23*100,0)) -> 0 | AA23: בינוני | AC23: ILS | AD23: לא | AE23: 180
A24: PRA-05 | B24: הגנה — גישה וזהות | C24: PRA | D24: מדיניות סיסמאות חזקה ואיסור סיסמאות ברירת מחדל | E24: מדיניות סיסמאות חזקה ואיסור סיסמאות ברירת מחדל | G24: מדיניות סיסמאות חלשה או שימוש בסיסמאות ברירת מחדל עלולים לאפשר פריצה באמצעות brute-force, ניצול credential stuffing והשתלטות על מערכות עם סיסמאות צפויות | H24: 4 | I24: 4 | J24: =IF(OR(H24="",I24=""),"",H24*I24) -> 16 | K24: =IF(J24="","",IF(J24>=12,"קריטי",IF(J24>=8,"גבוה",IF(J24>=4,"בינוני","נמוך")))) -> קריטי | L24: מהנדס אבטחה | M24: 1. הגדרת מדיניות סיסמאות חזקה — אורך, מורכבות וחילוף (NIST IA-5(1)) 2. חסימת סיסמאות נפוצות ומילוניות (IA-5(1)(a)) 3. ביטול סיסמאות ברירת מחדל בכל מערכת וציוד (IA-5(1), CM-6) 4. שימוש בכלי בדיקת חוזק סיסמאות ומעקב אחר דליפות (IA-5(2)) | N24: 2 | O24: 1 | P24: =IF(OR(N24="",O24=""),"",N24*O24) -> 2 | Q24: =IF(P24="","",IF(P24>=12,"קריטי",IF(P24>=8,"גבוה",IF(P24>=4,"בינוני","נמוך")))) -> נמוך | R24: =IF(J24="","",IF(X24>0,ROUND(J24-IF(T24="הושלם",1,Z24/100)*(J24-IF(P24="",J24,P24)),0),IF(T24="הושלם",IF(P24="",J24,P24),IF(T24="בתהליך",IF(P24="",J24,ROUND((J24+P24)/2,0)),J24)))) -> 9 | S24: =IF(R24="","",IF(R24>=12,"קריטי",IF(R24>=8,"גבוה",IF(R24>=4,"בינוני","נמוך")))) -> גבוה | T24: בתהליך | V24: הפחתת סיכון | W24: לא | X24: 0 | Y24: 0 | Z24: =IF(X24=0,0,ROUND(Y24/X24*100,0)) -> 0 | AA24: קל | AC24: ILS | AD24: לא
A25: PRA-06 | B25: הגנה — גישה וזהות | C25: PRA | D25: הפרדת תפקידים (SoD) במערכות קריטיות | E25: הפרדת תפקידים (SoD) במערכות קריטיות | G25: היעדר הפרדת תפקידים (SoD) עלול לאפשר לגורם יחיד לבצע פעולות הונאה ללא בקרה, לשנות הגדרות אבטחה ולמחוק עקבות ללא פיקוח | J25: =IF(OR(H25="",I25=""),"",H25*I25) | K25: =IF(J25="","",IF(J25>=12,"קריטי",IF(J25>=8,"גבוה",IF(J25>=4,"בינוני","נמוך")))) | L25: GRC | M25: 1. הגדרת מטריצת הפרדת תפקידים (SoD) במערכות קריטיות (NIST AC-5) 2. מניעת ריכוז הרשאות סותרות באותו משתמש (AC-5) 3. אכיפה טכנולוגית של SoD במערכות ERP ותשתית (AC-5, AC-6) 4. סקירה תקופתית לאיתור הפרות SoD ותיקונן (AC-5, AC-2(13)) | P25: =IF(OR(N25="",O25=""),"",N25*O25) | Q25: =IF(P25="","",IF(P25>=12,"קריטי",IF(P25>=8,"גבוה",IF(P25>=4,"בינוני","נמוך")))) | R25: =IF(J25="","",IF(X25>0,ROUND(J25-IF(T25="הושלם",1,Z25/100)*(J25-IF(P25="",J25,P25)),0),IF(T25="הושלם",IF(P25="",J25,P25),IF(T25="בתהליך",IF(P25="",J25,ROUND((J25+P25)/2,0)),J25)))) | S25: =IF(R25="","",IF(R25>=12,"קריטי",IF(R25>=8,"גבוה",IF(R25>=4,"בינוני","נמוך")))) | T25: לא התחיל | W25: לא | X25: 0 | Y25: 0 | Z25: =IF(X25=0,0,ROUND(Y25/X25*100,0)) -> 0 | AC25: ILS | AD25: לא
A26: PRN-01 | B26: הגנה — רשת ותשתית | C26: PRN | D26: סגמנטציה והפרדת רשתות לפי רמות אמון | E26: סגמנטציה והפרדת רשתות לפי רמות אמון | G26: היעדר סגמנטציה והפרדת רשתות עלול לאפשר תנועה רוחבית חופשית של תוקף, התפשטות כופרה (ransomware) בכלל הרשת וגישה לנכסים קריטיים ממגזר שנפרץ | J26: =IF(OR(H26="",I26=""),"",H26*I26) | K26: =IF(J26="","",IF(J26>=12,"קריטי",IF(J26>=8,"גבוה",IF(J26>=4,"בינוני","נמוך")))) | L26: מהנדס רשת | M26: 1. ביצוע סגמנטציה פיזית/לוגית בין רשתות לפי רמות אמון (NIST SC-7, SC-7(21)) 2. הגדרת VLANs, zones ו-trust boundaries (SC-7(22)) 3. שימוש ב-micro-segmentation לנכסים קריטיים (SC-7(29)) 4. חסימת תעבורה בין מגזרים אלא אם הותרה מפורשות (SC-7, AC-4) | P26: =IF(OR(N26="",O26=""),"",N26*O26) | Q26: =IF(P26="","",IF(P26>=12,"קריטי",IF(P26>=8,"גבוה",IF(P26>=4,"בינוני","נמוך")))) | R26: =IF(J26="","",IF(X26>0,ROUND(J26-IF(T26="הושלם",1,Z26/100)*(J26-IF(P26="",J26,P26)),0),IF(T26="הושלם",IF(P26="",J26,P26),IF(T26="בתהליך",IF(P26="",J26,ROUND((J26+P26)/2,0)),J26)))) | S26: =IF(R26="","",IF(R26>=12,"קריטי",IF(R26>=8,"גבוה",IF(R26>=4,"בינוני","נמוך")))) | T26: לא התחיל | W26: לא | X26: 0 | Y26: 0 | Z26: =IF(X26=0,0,ROUND(Y26/X26*100,0)) -> 0 | AC26: ILS | AD26: לא
A27: PRN-02 | B27: הגנה — רשת ותשתית | C27: PRN | D27: הגנת היקף — Firewall/NGFW ומדיניות deny-by-default | E27: הגנת היקף — Firewall/NGFW ומדיניות deny-by-default | G27: היעדר הגנת היקף ומדיניות deny-by-default עלולים לאפשר תעבורה זדונית, גישה בלתי מורשית מהאינטרנט וניצול שירותים חשופים כווקטורי תקיפה ראשוניים | J27: =IF(OR(H27="",I27=""),"",H27*I27) | K27: =IF(J27="","",IF(J27>=12,"קריטי",IF(J27>=8,"גבוה",IF(J27>=4,"בינוני","נמוך")))) | L27: מהנדס אבטחה | M27: 1. הטמעת NGFW עם מדיניות deny-by-default בכל נקודות הגבול (NIST SC-7) 2. הגדרת חוקי Firewall מינימליים ומפורשים (SC-7(5)) 3. סקירה תקופתית של חוקי Firewall והסרת חוקים מיותרים (SC-7(4)) 4. ניטור והתרעה על תעבורה חסומה וחריגה (SC-7(9), SI-4) | P27: =IF(OR(N27="",O27=""),"",N27*O27) | Q27: =IF(P27="","",IF(P27>=12,"קריטי",IF(P27>=8,"גבוה",IF(P27>=4,"בינוני","נמוך")))) | R27: =IF(J27="","",IF(X27>0,ROUND(J27-IF(T27="הושלם",1,Z27/100)*(J27-IF(P27="",J27,P27)),0),IF(T27="הושלם",IF(P27="",J27,P27),IF(T27="בתהליך",IF(P27="",J27,ROUND((J27+P27)/2,0)),J27)))) | S27: =IF(R27="","",IF(R27>=12,"קריטי",IF(R27>=8,"גבוה",IF(R27>=4,"בינוני","נמוך")))) | T27: לא התחיל | W27: לא | X27: 0 | Y27: 0 | Z27: =IF(X27=0,0,ROUND(Y27/X27*100,0)) -> 0 | AC27: ILS | AD27: לא
A28: PRN-03 | B28: הגנה — רשת ותשתית | C28: PRN | D28: מערכות מניעת חדירות (IPS) בנקודות הגבול | E28: מערכות מניעת חדירות (IPS) בנקודות הגבול | G28: היעדר מערכות IPS בנקודות הגבול עלול לאפשר חדירת תעבורה זדונית, ניצול חולשות ידועות מבחוץ ותקשורת C2 (פיקוד ושליטה) ללא חסימה | J28: =IF(OR(H28="",I28=""),"",H28*I28) | K28: =IF(J28="","",IF(J28>=12,"קריטי",IF(J28>=8,"גבוה",IF(J28>=4,"בינוני","נמוך")))) | L28: NetOps | M28: 1. הטמעת IPS/IDS בנקודות הגבול ובין מגזרי רשת (NIST SI-4, SC-7) 2. עדכון חתימות IPS באופן שוטף ואוטומטי (SI-4(2)) 3. כיול חוקי IPS למניעת false positives/negatives (SI-4(5)) 4. שילוב התראות IPS עם מערכת SIEM לתגובה מהירה (SI-4(16)) | P28: =IF(OR(N28="",O28=""),"",N28*O28) | Q28: =IF(P28="","",IF(P28>=12,"קריטי",IF(P28>=8,"גבוה",IF(P28>=4,"בינוני","נמוך")))) | R28: =IF(J28="","",IF(X28>0,ROUND(J28-IF(T28="הושלם",1,Z28/100)*(J28-IF(P28="",J28,P28)),0),IF(T28="הושלם",IF(P28="",J28,P28),IF(T28="בתהליך",IF(P28="",J28,ROUND((J28+P28)/2,0)),J28)))) | S28: =IF(R28="","",IF(R28>=12,"קריטי",IF(R28>=8,"גבוה",IF(R28>=4,"בינוני","נמוך")))) | T28: לא התחיל | W28: לא | X28: 0 | Y28: 0 | Z28: =IF(X28=0,0,ROUND(Y28/X28*100,0)) -> 0 | AC28: ILS | AD28: לא
A29: PRN-04 | B29: הגנה — רשת ותשתית | C29: PRN | D29: הגנה מפני מניעת שירות (DoS/DDoS) | E29: הגנה מפני מניעת שירות (DoS/DDoS) | G29: היעדר הגנה מפני DoS/DDoS עלול לגרום להשבתת שירותים קריטיים, אובדן זמינות מערכות ופגיעה כלכלית ותדמיתית כתוצאה מהצפת משאבי הרשת | J29: =IF(OR(H29="",I29=""),"",H29*I29) | K29: =IF(J29="","",IF(J29>=12,"קריטי",IF(J29>=8,"גבוה",IF(J29>=4,"בינוני","נמוך")))) | L29: מהנדס אבטחה | M29: 1. הטמעת פתרון הגנה מפני DDoS (on-prem או cloud-based) (NIST SC-5) 2. הגדרת ספי עומס (rate limiting) וחסימת תעבורה חריגה (SC-5) 3. תכנון יתירות (redundancy) בקישוריות אינטרנט (SC-5, CP-8) 4. הגדרת נהלי תגובה ייעודיים לאירועי DDoS (IR-4, SC-5) | P29: =IF(OR(N29="",O29=""),"",N29*O29) | Q29: =IF(P29="","",IF(P29>=12,"קריטי",IF(P29>=8,"גבוה",IF(P29>=4,"בינוני","נמוך")))) | R29: =IF(J29="","",IF(X29>0,ROUND(J29-IF(T29="הושלם",1,Z29/100)*(J29-IF(P29="",J29,P29)),0),IF(T29="הושלם",IF(P29="",J29,P29),IF(T29="בתהליך",IF(P29="",J29,ROUND((J29+P29)/2,0)),J29)))) | S29: =IF(R29="","",IF(R29>=12,"קריטי",IF(R29>=8,"גבוה",IF(R29>=4,"בינוני","נמוך")))) | T29: לא התחיל | W29: לא | X29: 0 | Y29: 0 | Z29: =IF(X29=0,0,ROUND(Y29/X29*100,0)) -> 0 | AC29: ILS | AD29: לא
A30: PRN-05 | B30: הגנה — רשת ותשתית | C30: PRN | D30: אבטחת גישה מרחוק ו-VPN מוקשח | E30: אבטחת גישה מרחוק ו-VPN מוקשח | G30: חולשות באבטחת גישה מרחוק ו-VPN עלולות לאפשר לתוקף חיצוני לחדור לרשת הפנימית, ליירט תעבורה מוצפנת או לנצל תצורה שגויה לגישה בלתי מורשית | J30: =IF(OR(H30="",I30=""),"",H30*I30) | K30: =IF(J30="","",IF(J30>=12,"קריטי",IF(J30>=8,"גבוה",IF(J30>=4,"בינוני","נמוך")))) | L30: מנהל IR | M30: 1. הקשחת שירות VPN — פרוטוקולים חזקים, הצפנה מעודכנת (NIST SC-8, SC-12, SC-13) 2. אכיפת MFA על כל חיבור VPN (IA-2(1), IA-2(6)) 3. הגבלת גישת VPN לפי תפקיד ונכסים נדרשים בלבד (AC-4, AC-17) 4. ניטור חיבורי VPN ואיתור התנהגות חריגה (AC-17(1), SI-4) | P30: =IF(OR(N30="",O30=""),"",N30*O30) | Q30: =IF(P30="","",IF(P30>=12,"קריטי",IF(P30>=8,"גבוה",IF(P30>=4,"בינוני","נמוך")))) | R30: =IF(J30="","",IF(X30>0,ROUND(J30-IF(T30="הושלם",1,Z30/100)*(J30-IF(P30="",J30,P30)),0),IF(T30="הושלם",IF(P30="",J30,P30),IF(T30="בתהליך",IF(P30="",J30,ROUND((J30+P30)/2,0)),J30)))) | S30: =IF(R30="","",IF(R30>=12,"קריטי",IF(R30>=8,"גבוה",IF(R30>=4,"בינוני","נמוך")))) | T30: לא התחיל | W30: לא | X30: 0 | Y30: 0 | Z30: =IF(X30=0,0,ROUND(Y30/X30*100,0)) -> 0 | AC30: ILS | AD30: לא
A31: PRN-06 | B31: הגנה — רשת ותשתית | C31: PRN | D31: הקשחת תצורת ציוד רשת לפי best practices | E31: הקשחת תצורת ציוד רשת לפי best practices | G31: היעדר הקשחת ציוד רשת עלולה לאפשר ניצול הגדרות ברירת מחדל, השתלטות על ציוד תשתיתי (נתבים, מתגים) והפניית תעבורה לשרתי תוקף | J31: =IF(OR(H31="",I31=""),"",H31*I31) | K31: =IF(J31="","",IF(J31>=12,"קריטי",IF(J31>=8,"גבוה",IF(J31>=4,"בינוני","נמוך")))) | L31: מהנדס רשת | M31: 1. הקשחת ציוד רשת (נתבים, מתגים, AP) לפי CIS Benchmarks (NIST CM-6, CM-7) 2. ביטול שירותים, פורטים ופרוטוקולים לא נדרשים (CM-7) 3. שימוש ב-SNMPv3, ביטול telnet ושימוש ב-SSH בלבד (SC-8, CM-6) 4. גיבוי תצורות ובקרת שינויים על ציוד רשת (CM-3, CM-6) | P31: =IF(OR(N31="",O31=""),"",N31*O31) | Q31: =IF(P31="","",IF(P31>=12,"קריטי",IF(P31>=8,"גבוה",IF(P31>=4,"בינוני","נמוך")))) | R31: =IF(J31="","",IF(X31>0,ROUND(J31-IF(T31="הושלם",1,Z31/100)*(J31-IF(P31="",J31,P31)),0),IF(T31="הושלם",IF(P31="",J31,P31),IF(T31="בתהליך",IF(P31="",J31,ROUND((J31+P31)/2,0)),J31)))) | S31: =IF(R31="","",IF(R31>=12,"קריטי",IF(R31>=8,"גבוה",IF(R31>=4,"בינוני","נמוך")))) | T31: לא התחיל | W31: לא | X31: 0 | Y31: 0 | Z31: =IF(X31=0,0,ROUND(Y31/X31*100,0)) -> 0 | AC31: ILS | AD31: לא
A32: PRN-07 | B32: הגנה — רשת ותשתית | C32: PRN | D32: הגנה והקשחת שירותי DNS | E32: הגנה והקשחת שירותי DNS | G32: היעדר הגנה והקשחת DNS עלולים לאפשר מתקפות DNS poisoning/spoofing, הפניית משתמשים לאתרים זדוניים ויירוט תעבורה באמצעות שליטה בתשובות DNS | J32: =IF(OR(H32="",I32=""),"",H32*I32) | K32: =IF(J32="","",IF(J32>=12,"קריטי",IF(J32>=8,"גבוה",IF(J32>=4,"בינוני","נמוך")))) | L32: GRC | M32: 1. הקשחת שרתי DNS — הגבלת zone transfer, ביטול רקורסיה מיותרת (NIST SC-20, SC-21) 2. הטמעת DNSSEC לאימות תשובות DNS (SC-20) 3. שימוש ב-DNS sinkhole לחסימת דומיינים זדוניים (SC-20, SC-7) 4. ניטור שאילתות DNS חריגות לזיהוי DNS tunneling ו-C2 (SI-4, SC-7) | P32: =IF(OR(N32="",O32=""),"",N32*O32) | Q32: =IF(P32="","",IF(P32>=12,"קריטי",IF(P32>=8,"גבוה",IF(P32>=4,"בינוני","נמוך")))) | R32: =IF(J32="","",IF(X32>0,ROUND(J32-IF(T32="הושלם",1,Z32/100)*(J32-IF(P32="",J32,P32)),0),IF(T32="הושלם",IF(P32="",J32,P32),IF(T32="בתהליך",IF(P32="",J32,ROUND((J32+P32)/2,0)),J32)))) | S32: =IF(R32="","",IF(R32>=12,"קריטי",IF(R32>=8,"גבוה",IF(R32>=4,"בינוני","נמוך")))) | T32: לא התחיל | W32: לא | X32: 0 | Y32: 0 | Z32: =IF(X32=0,0,ROUND(Y32/X32*100,0)) -> 0 | AC32: ILS | AD32: לא
A33: PRE-01 | B33: הגנה — קצה ושרתים | C33: PRE | D33: הקשחת תחנות קצה ושרתים (baseline/CIS) | E33: הקשחת תחנות קצה ושרתים (baseline/CIS) | G33: היעדר הקשחת תחנות קצה ושרתים עלולה לאפשר ניצול הגדרות חלשות, הרצת קוד זדוני ושימוש בשירותים מיותרים כנקודות כניסה לתוקף | H33: 4 | I33: 4 | J33: =IF(OR(H33="",I33=""),"",H33*I33) -> 16 | K33: =IF(J33="","",IF(J33>=12,"קריטי",IF(J33>=8,"גבוה",IF(J33>=4,"בינוני","נמוך")))) -> קריטי | L33: מנהל מערכת | M33: 1. הקשחת תחנות קצה ושרתים לפי CIS Benchmarks / STIG (NIST CM-6, CM-7) 2. ביטול שירותים ופורטים לא נדרשים (CM-7(1)) 3. הפעלת host-based firewall בכל תחנה ושרת (SC-7(12)) 4. שימוש ב-GPO/MDM לאכיפת תצורות אחידות (CM-6, CM-2) | N33: 2 | O33: 2 | P33: =IF(OR(N33="",O33=""),"",N33*O33) -> 4 | Q33: =IF(P33="","",IF(P33>=12,"קריטי",IF(P33>=8,"גבוה",IF(P33>=4,"בינוני","נמוך")))) -> בינוני | R33: =IF(J33="","",IF(X33>0,ROUND(J33-IF(T33="הושלם",1,Z33/100)*(J33-IF(P33="",J33,P33)),0),IF(T33="הושלם",IF(P33="",J33,P33),IF(T33="בתהליך",IF(P33="",J33,ROUND((J33+P33)/2,0)),J33)))) -> 8 | S33: =IF(R33="","",IF(R33>=12,"קריטי",IF(R33>=8,"גבוה",IF(R33>=4,"בינוני","נמוך")))) -> גבוה | T33: לא התחיל | V33: הפחתת סיכון | W33: לא | X33: 3 | Y33: 2 | Z33: =IF(X33=0,0,ROUND(Y33/X33*100,0)) -> 67 | AA33: מורכב | AB33: 8656 | AC33: ILS | AD33: לא
A34: PRE-02 | B34: הגנה — קצה ושרתים | C34: PRE | D34: הגנת קצה מתקדמת (EDR/AV) ומניעת קוד זדוני | E34: הגנת קצה מתקדמת (EDR/AV) ומניעת קוד זדוני | G34: היעדר הגנת קצה מתקדמת (EDR/AV) עלול לאפשר הרצת קוד זדוני, כופרה ותוכנות ריגול ללא זיהוי, ופעילות תוקף בלתי מזוהה בתחנות הקצה | H34: 4 | I34: 4 | J34: =IF(OR(H34="",I34=""),"",H34*I34) -> 16 | K34: =IF(J34="","",IF(J34>=12,"קריטי",IF(J34>=8,"גבוה",IF(J34>=4,"בינוני","נמוך")))) -> קריטי | L34: מנהל מערכת | M34: 1. הטמעת פתרון EDR/AV מתקדם בכל תחנה ושרת (NIST SI-3, SI-4) 2. אכיפת עדכון חתימות אוטומטי ורציף (SI-3(1)) 3. הפעלת יכולות behavioral detection וזיכרון (SI-3, SI-4) 4. שילוב התראות EDR עם SIEM לתגובה מהירה (SI-4(16), IR-4) | N34: 3 | O34: 2 | P34: =IF(OR(N34="",O34=""),"",N34*O34) -> 6 | Q34: =IF(P34="","",IF(P34>=12,"קריטי",IF(P34>=8,"גבוה",IF(P34>=4,"בינוני","נמוך")))) -> בינוני | R34: =IF(J34="","",IF(X34>0,ROUND(J34-IF(T34="הושלם",1,Z34/100)*(J34-IF(P34="",J34,P34)),0),IF(T34="הושלם",IF(P34="",J34,P34),IF(T34="בתהליך",IF(P34="",J34,ROUND((J34+P34)/2,0)),J34)))) -> 16 | S34: =IF(R34="","",IF(R34>=12,"קריטי",IF(R34>=8,"גבוה",IF(R34>=4,"בינוני","נמוך")))) -> קריטי | T34: לא התחיל | V34: הפחתת סיכון | W34: לא | X34: 3 | Y34: 0 | Z34: =IF(X34=0,0,ROUND(Y34/X34*100,0)) -> 0 | AB34: 45648 | AC34: USD | AD34: לא
A35: PRE-03 | B35: הגנה — קצה ושרתים | C35: PRE | D35: ניהול עדכוני אבטחה (patching) לפי חומרה ו-SLA | E35: ניהול עדכוני אבטחה (patching) לפי חומרה ו-SLA | G35: היעדר ניהול עדכוני אבטחה (patching) עלול להותיר חולשות ידועות (CVE) פתוחות לניצול, לאפשר תקיפות אוטומטיות ולחשוף את הארגון למתקפות zero-day+1 | H35: 3 | I35: 3 | J35: =IF(OR(H35="",I35=""),"",H35*I35) -> 9 | K35: =IF(J35="","",IF(J35>=12,"קריטי",IF(J35>=8,"גבוה",IF(J35>=4,"בינוני","נמוך")))) -> גבוה | L35: ארכיטקט | M35: 1. הגדרת מדיניות patching עם SLA לפי חומרת פגיעות (NIST SI-2) 2. סריקה ויישום עדכונים קריטיים תוך 72 שעות (SI-2(2)) 3. בדיקת עדכונים בסביבת בדיקה לפני יישום בייצור (SI-2, CM-3) 4. מעקב ודיווח על מצב patching ואחוזי כיסוי (SI-2, CM-8) | N35: 3 | O35: 2 | P35: =IF(OR(N35="",O35=""),"",N35*O35) -> 6 | Q35: =IF(P35="","",IF(P35>=12,"קריטי",IF(P35>=8,"גבוה",IF(P35>=4,"בינוני","נמוך")))) -> בינוני | R35: =IF(J35="","",IF(X35>0,ROUND(J35-IF(T35="הושלם",1,Z35/100)*(J35-IF(P35="",J35,P35)),0),IF(T35="הושלם",IF(P35="",J35,P35),IF(T35="בתהליך",IF(P35="",J35,ROUND((J35+P35)/2,0)),J35)))) -> 6 | S35: =IF(R35="","",IF(R35>=12,"קריטי",IF(R35>=8,"גבוה",IF(R35>=4,"בינוני","נמוך")))) -> בינוני | T35: לא התחיל | V35: הפחתת סיכון | W35: לא | X35: 3 | Y35: 3 | Z35: =IF(X35=0,0,ROUND(Y35/X35*100,0)) -> 100 | AA35: בינוני | AC35: ILS | AD35: לא
A36: PRE-04 | B36: הגנה — קצה ושרתים | C36: PRE | D36: ניהול פגיעויות וסריקות תקופתיות | E36: ניהול פגיעויות וסריקות תקופתיות | G36: היעדר ניהול פגיעויות וסריקות תקופתיות עלול להותיר חולשות בלתי מזוהות במערכות, להגדיל את משטח התקיפה ולאפשר לתוקפים לנצל פגיעויות שלא תוקנו | H36: 3 | I36: 3 | J36: =IF(OR(H36="",I36=""),"",H36*I36) -> 9 | K36: =IF(J36="","",IF(J36>=12,"קריטי",IF(J36>=8,"גבוה",IF(J36>=4,"בינוני","נמוך")))) -> גבוה | L36: GRC | M36: 1. ביצוע סריקות פגיעויות תקופתיות (לפחות חודשיות) בכל המערכות (NIST RA-5) 2. שימוש בכלי סריקה מאושרים ומעודכנים (RA-5(2)) 3. תעדוף טיפול בפגיעויות לפי CVSS וקריטיות הנכס (RA-5(3)) 4. מעקב אחר סגירת פגיעויות ודיווח תקופתי (RA-5, CA-5) | N36: 2 | O36: 2 | P36: =IF(OR(N36="",O36=""),"",N36*O36) -> 4 | Q36: =IF(P36="","",IF(P36>=12,"קריטי",IF(P36>=8,"גבוה",IF(P36>=4,"בינוני","נמוך")))) -> בינוני | R36: =IF(J36="","",IF(X36>0,ROUND(J36-IF(T36="הושלם",1,Z36/100)*(J36-IF(P36="",J36,P36)),0),IF(T36="הושלם",IF(P36="",J36,P36),IF(T36="בתהליך",IF(P36="",J36,ROUND((J36+P36)/2,0)),J36)))) -> 9 | S36: =IF(R36="","",IF(R36>=12,"קריטי",IF(R36>=8,"גבוה",IF(R36>=4,"בינוני","נמוך")))) -> גבוה | T36: לא התחיל | V36: הפחתת סיכון | W36: לא | X36: 2 | Y36: 0 | Z36: =IF(X36=0,0,ROUND(Y36/X36*100,0)) -> 0 | AC36: ILS | AD36: לא
A37: PRE-05 | B37: הגנה — קצה ושרתים | C37: PRE | D37: מניעת הרצת תוכנה לא מורשית (allow-listing) | E37: מניעת הרצת תוכנה לא מורשית (allow-listing) | G37: היעדר מניעת הרצת תוכנה לא מורשית עלול לאפשר הרצת כלי תקיפה, כופרה ותוכנות ריגול על תחנות קצה ושרתים, תוך עקיפת בקרות אבטחה קיימות | H37: 4 | I37: 4 | J37: =IF(OR(H37="",I37=""),"",H37*I37) -> 16 | K37: =IF(J37="","",IF(J37>=12,"קריטי",IF(J37>=8,"גבוה",IF(J37>=4,"בינוני","נמוך")))) -> קריטי | L37: מהנדס אבטחה | M37: 1. הטמעת application whitelisting / allow-listing בתחנות ושרתים (NIST CM-7(5)) 2. חסימת הרצת קבצי הפעלה ממיקומים לא מורשים (CM-7(5)) 3. ניהול רשימה לבנה מעודכנת של תוכנות מאושרות (CM-7(5), CM-8) 4. ניטור והתרעה על ניסיונות הרצת תוכנה לא מורשית (SI-4, AU-12) | N37: 2 | O37: 2 | P37: =IF(OR(N37="",O37=""),"",N37*O37) -> 4 | Q37: =IF(P37="","",IF(P37>=12,"קריטי",IF(P37>=8,"גבוה",IF(P37>=4,"בינוני","נמוך")))) -> בינוני | R37: =IF(J37="","",IF(X37>0,ROUND(J37-IF(T37="הושלם",1,Z37/100)*(J37-IF(P37="",J37,P37)),0),IF(T37="הושלם",IF(P37="",J37,P37),IF(T37="בתהליך",IF(P37="",J37,ROUND((J37+P37)/2,0)),J37)))) -> 16 | S37: =IF(R37="","",IF(R37>=12,"קריטי",IF(R37>=8,"גבוה",IF(R37>=4,"בינוני","נמוך")))) -> קריטי | T37: לא התחיל | V37: הפחתת סיכון | W37: לא | X37: 1 | Y37: 0 | Z37: =IF(X37=0,0,ROUND(Y37/X37*100,0)) -> 0 | AA37: מורכב | AC37: ILS | AD37: לא
A38: PRE-06 | B38: הגנה — קצה ושרתים | C38: PRE | D38: אבטחת תצורה והקשחה של מערכות הפעלה ויישומים | E38: אבטחת תצורה והקשחה של מערכות הפעלה ויישומים | G38: היעדר הקשחת מערכות הפעלה ויישומים עלולה לחשוף את הארגון לניצול הגדרות ברירת מחדל, שירותים פגיעים פתוחים ומשטח תקיפה מורחב | H38: 3 | I38: 3 | J38: =IF(OR(H38="",I38=""),"",H38*I38) -> 9 | K38: =IF(J38="","",IF(J38>=12,"קריטי",IF(J38>=8,"גבוה",IF(J38>=4,"בינוני","נמוך")))) -> גבוה | L38: אנליסט SOC | M38: 1. הקשחת מערכות הפעלה ויישומים לפי תקני CIS/STIG (NIST CM-6, CM-7) 2. השבתת שירותים ותכונות שאינם בשימוש (CM-7) 3. אכיפת תצורות baseline מאושרות (CM-2, CM-6) 4. סריקות ציות תקופתיות לאימות עמידה ב-baseline (CM-6, CA-7) | N38: 2 | O38: 1 | P38: =IF(OR(N38="",O38=""),"",N38*O38) -> 2 | Q38: =IF(P38="","",IF(P38>=12,"קריטי",IF(P38>=8,"גבוה",IF(P38>=4,"בינוני","נמוך")))) -> נמוך | R38: =IF(J38="","",IF(X38>0,ROUND(J38-IF(T38="הושלם",1,Z38/100)*(J38-IF(P38="",J38,P38)),0),IF(T38="הושלם",IF(P38="",J38,P38),IF(T38="בתהליך",IF(P38="",J38,ROUND((J38+P38)/2,0)),J38)))) -> 6 | S38: =IF(R38="","",IF(R38>=12,"קריטי",IF(R38>=8,"גבוה",IF(R38>=4,"בינוני","נמוך")))) -> בינוני | T38: בתהליך | V38: הפחתת סיכון | W38: לא | X38: 0 | Y38: 0 | Z38: =IF(X38=0,0,ROUND(Y38/X38*100,0)) -> 0 | AC38: ILS | AD38: לא
A39: PRD-01 | B39: הגנה — מידע | C39: PRD | D39: הצפנת מידע רגיש במנוחה (at-rest) | E39: הצפנת מידע רגיש במנוחה (at-rest) | G39: היעדר הצפנת מידע רגיש במנוחה עלול לאפשר גישה למידע רגיש במקרה של גניבת דיסקים, גיבויים או גישה פיזית בלתי מורשית לשרתים | H39: 2 | I39: 1 | J39: =IF(OR(H39="",I39=""),"",H39*I39) -> 2 | K39: =IF(J39="","",IF(J39>=12,"קריטי",IF(J39>=8,"גבוה",IF(J39>=4,"בינוני","נמוך")))) -> נמוך | L39: מהנדס אבטחה | M39: 1. הצפנת מידע רגיש במנוחה באמצעות AES-256 או חזק יותר (NIST SC-28) 2. הצפנת דיסקים מלאים (FDE) בתחנות ניידות (SC-28(1)) 3. הצפנת בסיסי נתונים המכילים מידע רגיש (SC-28) 4. ניהול מפתחות הצפנה בהתאם למדיניות (SC-12) | N39: 1 | O39: 1 | P39: =IF(OR(N39="",O39=""),"",N39*O39) -> 1 | Q39: =IF(P39="","",IF(P39>=12,"קריטי",IF(P39>=8,"גבוה",IF(P39>=4,"בינוני","נמוך")))) -> נמוך | R39: =IF(J39="","",IF(X39>0,ROUND(J39-IF(T39="הושלם",1,Z39/100)*(J39-IF(P39="",J39,P39)),0),IF(T39="הושלם",IF(P39="",J39,P39),IF(T39="בתהליך",IF(P39="",J39,ROUND((J39+P39)/2,0)),J39)))) -> 2 | S39: =IF(R39="","",IF(R39>=12,"קריטי",IF(R39>=8,"גבוה",IF(R39>=4,"בינוני","נמוך")))) -> נמוך | T39: לא התחיל | V39: קבלת הסיכון | W39: לא | X39: 0 | Y39: 0 | Z39: =IF(X39=0,0,ROUND(Y39/X39*100,0)) -> 0 | AC39: ILS | AD39: לא
A40: PRD-02 | B40: הגנה — מידע | C40: PRD | D40: הצפנת מידע בתעבורה (in-transit, TLS/IPsec) | E40: הצפנת מידע בתעבורה (in-transit, TLS/IPsec) | G40: היעדר הצפנת מידע בתעבורה עלול לאפשר יירוט (sniffing) של מידע רגיש ברשת, מתקפות Man-in-the-Middle וחשיפת אישורי גישה בתעבורה גלויה | H40: 2 | I40: 1 | J40: =IF(OR(H40="",I40=""),"",H40*I40) -> 2 | K40: =IF(J40="","",IF(J40>=12,"קריטי",IF(J40>=8,"גבוה",IF(J40>=4,"בינוני","נמוך")))) -> נמוך | L40: מנהל מערכת | M40: 1. אכיפת TLS 1.2+ בכל תעבורה חיצונית ופנימית רגישה (NIST SC-8, SC-8(1)) 2. שימוש ב-IPsec לתעבורה בין אתרים (SC-8) 3. ביטול פרוטוקולים לא מוצפנים (HTTP, FTP, Telnet) (SC-8(1)) 4. ניטור שימוש בגרסאות הצפנה חלשות או פגות (SC-13, SI-4) | N40: 1 | O40: 1 | P40: =IF(OR(N40="",O40=""),"",N40*O40) -> 1 | Q40: =IF(P40="","",IF(P40>=12,"קריטי",IF(P40>=8,"גבוה",IF(P40>=4,"בינוני","נמוך")))) -> נמוך | R40: =IF(J40="","",IF(X40>0,ROUND(J40-IF(T40="הושלם",1,Z40/100)*(J40-IF(P40="",J40,P40)),0),IF(T40="הושלם",IF(P40="",J40,P40),IF(T40="בתהליך",IF(P40="",J40,ROUND((J40+P40)/2,0)),J40)))) -> 2 | S40: =IF(R40="","",IF(R40>=12,"קריטי",IF(R40>=8,"גבוה",IF(R40>=4,"בינוני","נמוך")))) -> נמוך | T40: לא התחיל | V40: קבלת הסיכון | W40: לא | X40: 0 | Y40: 0 | Z40: =IF(X40=0,0,ROUND(Y40/X40*100,0)) -> 0 | AC40: ILS | AD40: לא
...

Sheet פעולות מיטיגציה
A1: בקרה — קוד | B1: בקרה — שם | C1: משפחה | D1: פעולת מיטיגציה | E1: בוצעה?
A2: GOV-02 | B2: מינוי ממונה הגנת סייבר (CISO) והגדרת סמכויותיו | C2: ממשל וניהול סיכונים | D2: 1. מינוי CISO/ממונה סייבר בכיר עם דיווח ישיר להנהלה (NIST PM-2) | E2: לא
A3: GOV-02 | B3: מינוי ממונה הגנת סייבר (CISO) והגדרת סמכויותיו | C3: ממשל וניהול סיכונים | D3: 4. שיבוץ CISO בפורום הנהלה ובוועדת סיכונים (PM-29) | E3: לא
A4: GOV-02 | B4: מינוי ממונה הגנת סייבר (CISO) והגדרת סמכויותיו | C4: ממשל וניהול סיכונים | D4: 3. הקצאת צוות ומשאבים ייעודיים לממונה (PM-3) | E4: לא
A5: PRA-02 | B5: אכיפת עקרון הרשאות מינימום (least privilege) | C5: הגנה — גישה וזהות | D5: 1. יישום עקרון least privilege בכל מערכת ואפליקציה (NIST AC-6) | E5: כן
A6: PRA-02 | B6: אכיפת עקרון הרשאות מינימום (least privilege) | C6: הגנה — גישה וזהות | D6: 2. הגבלת גישה לפי תפקיד (RBAC) עם הרשאות מינימליות (AC-6(1)) | E6: כן
A7: PRA-02 | B7: אכיפת עקרון הרשאות מינימום (least privilege) | C7: הגנה — גישה וזהות | D7: 4. סקירת הרשאות תקופתית וצמצום הרשאות עודפות (AC-6(7), AC-2(13)) | E7: כן
A8: PRE-01 | B8: הקשחת תחנות קצה ושרתים (baseline/CIS) | C8: הגנה — קצה ושרתים | D8: 1. הקשחת תחנות קצה ושרתים לפי CIS Benchmarks / STIG (NIST CM-6, CM-7) | E8: כן
A9: PRE-01 | B9: הקשחת תחנות קצה ושרתים (baseline/CIS) | C9: הגנה — קצה ושרתים | D9: 2. ביטול שירותים ופורטים לא נדרשים (CM-7(1)) | E9: כן
A10: PRE-01 | B10: הקשחת תחנות קצה ושרתים (baseline/CIS) | C10: הגנה — קצה ושרתים | D10: 4. שימוש ב-GPO/MDM לאכיפת תצורות אחידות (CM-6, CM-2) | E10: לא
A11: PRE-02 | B11: הגנת קצה מתקדמת (EDR/AV) ומניעת קוד זדוני | C11: הגנה — קצה ושרתים | D11: 1. הטמעת פתרון EDR/AV מתקדם בכל תחנה ושרת (NIST SI-3, SI-4) | E11: לא
A12: PRE-02 | B12: הגנת קצה מתקדמת (EDR/AV) ומניעת קוד זדוני | C12: הגנה — קצה ושרתים | D12: 2. אכיפת עדכון חתימות אוטומטי ורציף (SI-3(1)) | E12: לא
... A24: DET-01 | B24: איסוף לוגים מרכזי מנכסים קריטיים (SIEM) | C24: גילוי וניטור | D24: להגדיר מערכת לוגים | E24: לא

Sheet משימות
A1: בקרה — קוד | B1: בקרה — שם | C1: משפחה | D1: משימה | E1: אחראי | F1: הערכת זמן | G1: יחידת זמן | H1: סטטוס
A2: DET-01 | B2: איסוף לוגים מרכזי מנכסים קריטיים (SIEM) | C2: גילוי וניטור | D2: להתקין מערכת איסוף לוגים מרכזית | E2: test1 | F2: 44 | G2: ימים | H2: בתהליך
A3: DET-01 | B3: איסוף לוגים מרכזי מנכסים קריטיים (SIEM) | C3: גילוי וניטור | D3: test1 | E3: test1 | F3: 22 | G3: ימים | H3: פתוחה

Sheet דשבורד
A1: דשבורד — תמונת מצב הסיכונים
A2: כל הנתונים מתעדכנים אוטומטית לפי גליון "הערכת סיכונים"
A4: ⚡ מדדים מצרפיים (KPI)
A5: סה"כ בקרות | B5: =COUNTA('הערכת סיכונים'!$A$3:$A$74)
A6: בקרות רלוונטיות | B6: =COUNTIF('הערכת סיכונים'!$W$3:$W$74,"לא")
A7: בקרות לא רלוונטיות | B7: =COUNTIF('הערכת סיכונים'!$W$3:$W$74,"כן")
A8: חשיפה קריטית נוכחית | B8: =COUNTIFS('הערכת סיכונים'!$S$3:$S$74,"קריטי",'הערכת סיכונים'!$W$3:$W$74,"לא")
A9: חשיפה גבוהה נוכחית | B9: =COUNTIFS('הערכת סיכונים'!$S$3:$S$74,"גבוה",'הערכת סיכונים'!$W$3:$W$74,"לא")
A10: ציון סיכון ממוצע (נוכחי) | B10: =IFERROR(AVERAGEIFS('הערכת סיכונים'!$R$3:$R$74,'הערכת סיכונים'!$W$3:$W$74,"לא",'הערכת סיכונים'!$R$3:$R$74,">0"),0)
A11: ציון מובנה ממוצע | B11: =IFERROR(AVERAGEIFS('הערכת סיכונים'!$J$3:$J$74,'הערכת סיכונים'!$W$3:$W$74,"לא",'הערכת סיכונים'!$J$3:$J$74,">0"),0)
A12: ציון שיורי ממוצע | B12: =IFERROR(AVERAGEIFS('הערכת סיכונים'!$P$3:$P$74,'הערכת סיכונים'!$W$3:$W$74,"לא",'הערכת סיכונים'!$P$3:$P$74,">0"),0)
A13: הופחת סיכון שהושג % | B13: =IFERROR(ROUND((SUMIFS('הערכת סיכונים'!$J$3:$J$74,'הערכת סיכונים'!$W$3:$W$74,"לא")-SUMIFS('הערכת סיכונים'!$R$3:$R$74,'הערכת סיכונים'!$W$3:$W$74,"לא"))/SUMIFS('הערכת סיכונים'!$J$3:$J$74,'הערכת סיכונים'!$W$3:$W$74,"לא")*100,0),0)
A14: הושלמו | B14: =COUNTIFS('הערכת סיכונים'!$T$3:$T$74,"הושלם",'הערכת סיכונים'!$W$3:$W$74,"לא")
A15: בתהליך | B15: =COUNTIFS('הערכת סיכונים'!$T$3:$T$74,"בתהליך",'הערכת סיכונים'!$W$3:$W$74,"לא")
A16: לא התחילו | B16: =COUNTIFS('הערכת סיכונים'!$T$3:$T$74,"לא התחיל",'הערכת סיכונים'!$W$3:$W$74,"לא")
A17: התקדמות טיפול משוקללת | B17: =IFERROR(ROUND((COUNTIFS('הערכת סיכונים'!$T$3:$T$74,"הושלם",'הערכת סיכונים'!$W$3:$W$74,"לא")*100+COUNTIFS('הערכת סיכונים'!$T$3:$T$74,"בתהליך",'הערכת סיכונים'!$W$3:$W$74,"לא")*50)/COUNTIF('הערכת סיכונים'!$W$3:$W$74,"לא"),0),0)
A19: 📊 התפלגות רמות סיכון
A20: רמה | B20: מובנה | C20: שיורי | D20: נוכחי
A21: קריטי | B21: =COUNTIFS('הערכת סיכונים'!$K$3:$K$74,"קריטי",'הערכת סיכונים'!$W$3:$W$74,"לא") | C21: =COUNTIFS('הערכת סיכונים'!$Q$3:$Q$74,"קריטי",'הערכת סיכונים'!$W$3:$W$74,"לא") | D21: =COUNTIFS('הערכת סיכונים'!$S$3:$S$74,"קריטי",'הערכת סיכונים'!$W$3:$W$74,"לא")
A22: גבוה | B22: =COUNTIFS('הערכת סיכונים'!$K$3:$K$74,"גבוה",'הערכת סיכונים'!$W$3:$W$74,"לא") | C22: =COUNTIFS('הערכת סיכונים'!$Q$3:$Q$74,"גבוה",'הערכת סיכונים'!$W$3:$W$74,"לא") | D22: =COUNTIFS('הערכת סיכונים'!$S$3:$S$74,"גבוה",'הערכת סיכונים'!$W$3:$W$74,"לא")
A23: בינוני | B23: =COUNTIFS('הערכת סיכונים'!$K$3:$K$74,"בינוני",'הערכת סיכונים'!$W$3:$W$74,"לא") | C23: =COUNTIFS('הערכת סיכונים'!$Q$3:$Q$74,"בינוני",'הערכת סיכונים'!$W$3:$W$74,"לא") | D23: =COUNTIFS('הערכת סיכונים'!$S$3:$S$74,"בינוני",'הערכת סיכונים'!$W$3:$W$74,"לא")
A24: נמוך | B24: =COUNTIFS('הערכת סיכונים'!$K$3:$K$74,"נמוך",'הערכת סיכונים'!$W$3:$W$74,"לא") | C24: =COUNTIFS('הערכת סיכונים'!$Q$3:$Q$74,"נמוך",'הערכת סיכונים'!$W$3:$W$74,"לא") | D24: =COUNTIFS('הערכת סיכונים'!$S$3:$S$74,"נמוך",'הערכת סיכונים'!$W$3:$W$74,"לא")
A26: 🚦 סטטוס טיפול
A27: סטטוס | B27: כמות
A28: הושלם | B28: =COUNTIFS('הערכת סיכונים'!$T$3:$T$74,"הושלם",'הערכת סיכונים'!$W$3:$W$74,"לא")
A29: בתהליך | B29: =COUNTIFS('הערכת סיכונים'!$T$3:$T$74,"בתהליך",'הערכת סיכונים'!$W$3:$W$74,"לא")
A30: לא התחיל | B30: =COUNTIFS('הערכת סיכונים'!$T$3:$T$74,"לא התחיל",'הערכת סיכונים'!$W$3:$W$74,"לא")
A32: 🧭 התפלגות החלטות הנהלה
A33: החלטה | B33: כמות
A34: הפחתת סיכון | B34: =COUNTIFS('הערכת סיכונים'!$V$3:$V$74,"הפחתת סיכון",'הערכת סיכונים'!$W$3:$W$74,"לא")
A35: העברת הסיכון | B35: =COUNTIFS('הערכת סיכונים'!$V$3:$V$74,"העברת הסיכון",'הערכת סיכונים'!$W$3:$W$74,"לא")
A36: קבלת הסיכון | B36: =COUNTIFS('הערכת סיכונים'!$V$3:$V$74,"קבלת הסיכון",'הערכת סיכונים'!$W$3:$W$74,"לא")
A37: הימנעות מהסיכון | B37: =COUNTIFS('הערכת סיכונים'!$V$3:$V$74,"הימנעות מהסיכון",'הערכת סיכונים'!$W$3:$W$74,"לא")
A38: ללא החלטה | B38: =COUNTIFS('הערכת סיכונים'!$V$3:$V$74,"",'הערכת סיכונים'!$W$3:$W$74,"לא")
A40: 🏷️ סיכומים לפי משפחה
A41: משפחה | B41: בקרות | C41: קריטי נוכחי | D41: גבוה נוכחי | E41: ציון מובנה ממוצע | F41: ציון נוכחי ממוצע | G41: % ביצוע מיטיגציה
A42: ממשל וניהול סיכונים | B42: =COUNTIFS('הערכת סיכונים'!$B$3:$B$74,"ממשל וניהול סיכונים",'הערכת סיכונים'!$W$3:$W$74,"לא") | C42: =COUNTIFS('הערכת סיכונים'!$B$3:$B$74,"ממשל וניהול סיכונים",'הערכת סיכונים'!$S$3:$S$74,"קריטי",'הערכת סיכונים'!$W$3:$W$74,"לא") | D42: =COUNTIFS('הערכת סיכונים'!$B$3:$B$74,"ממשל וניהול סיכונים",'הערכת סיכונים'!$S$3:$S$74,"גבוה",'הערכת סיכונים'!$W$3:$W$74,"לא") | E42: =IFERROR(AVERAGEIFS('הערכת סיכונים'!$J$3:$J$74,'הערכת סיכונים'!$B$3:$B$74,"ממשל וניהול סיכונים",'הערכת סיכונים'!$W$3:$W$74,"לא",'הערכת סיכונים'!$J$3:$J$74,">0"),0) | F42: =IFERROR(AVERAGEIFS('הערכת סיכונים'!$R$3:$R$74,'הערכת סיכונים'!$B$3:$B$74,"ממשל וניהול סיכונים",'הערכת סיכונים'!$W$3:$W$74,"לא",'הערכת סיכונים'!$R$3:$R$74,">0"),0) | G42: =IFERROR(AVERAGEIFS('הערכת סיכונים'!$Z$3:$Z$74,'הערכת סיכונים'!$B$3:$B$74,"ממשל וניהול סיכונים",'הערכת סיכונים'!$W$3:$W$74,"לא"),0)
A43: זיהוי ומיפוי נכסים | B43: =COUNTIFS('הערכת סיכונים'!$B$3:$B$74,"זיהוי ומיפוי נכסים",'הערכת סיכונים'!$W$3:$W$74,"לא") | C43: =COUNTIFS('הערכת סיכונים'!$B$3:$B$74,"זיהוי ומיפוי נכסים",'הערכת סיכונים'!$S$3:$S$74,"קריטי",'הערכת סיכונים'!$W$3:$W$74,"לא") | D43: =COUNTIFS('הערכת סיכונים'!$B$3:$B$74,"זיהוי ומיפוי נכסים",'הערכת סיכונים'!$S$3:$S$74,"גבוה",'הערכת סיכונים'!$W$3:$W$74,"לא") | E43: =IFERROR(AVERAGEIFS('הערכת סיכונים'!$J$3:$J$74,'הערכת סיכונים'!$B$3:$B$74,"זיהוי ומיפוי נכסים",'הערכת סיכונים'!$W$3:$W$74,"לא",'הערכת סיכונים'!$J$3:$J$74,">0"),0) | F43: =IFERROR(AVERAGEIFS('הערכת סיכונים'!$R$3:$R$74,'הערכת סיכונים'!$B$3:$B$74,"זיהוי ומיפוי נכסים",'הערכת סיכונים'!$W$3:$W$74,"לא",'הערכת סיכונים'!$R$3:$R$74,">0"),0) | G43: =IFERROR(AVERAGEIFS('הערכת סיכונים'!$Z$3:$Z$74,'הערכת סיכונים'!$B$3:$B$74,"זיהוי ומיפוי נכסים",'הערכת סיכונים'!$W$3:$W$74,"לא"),0)
A44: הגנה — גישה וזהות | B44: =COUNTIFS('הערכת סיכונים'!$B$3:$B$74,"הגנה — גישה וזהות",'הערכת סיכונים'!$W$3:$W$74,"לא") | C44: =COUNTIFS('הערכת סיכונים'!$B$3:$B$74,"הגנה — גישה וזהות",'הערכת סיכונים'!$S$3:$S$74,"קריטי",'הערכת סיכונים'!$W$3:$W$74,"לא") | D44: =COUNTIFS('הערכת סיכונים'!$B$3:$B$74,"הגנה — גישה וזהות",'הערכת סיכונים'!$S$3:$S$74,"גבוה",'הערכת סיכונים'!$W$3:$W$74,"לא") | E44: =IFERROR(AVERAGEIFS('הערכת סיכונים'!$J$3:$J$74,'הערכת סיכונים'!$B$3:$B$74,"הגנה — גישה וזהות",'הערכת סיכונים'!$W$3:$W$74,"לא",'הערכת סיכונים'!$J$3:$J$74,">0"),0) | F44: =IFERROR(AVERAGEIFS('הערכת סיכונים'!$R$3:$R$74,'הערכת סיכונים'!$B$3:$B$74,"הגנה — גישה וזהות",'הערכת סיכונים'!$W$3:$W$74,"לא",'הערכת סיכונים'!$R$3:$R$74,">0"),0) | G44: =IFERROR(AVERAGEIFS('הערכת סיכונים'!$Z$3:$Z$74,'הערכת סיכונים'!$B$3:$B$74,"הגנה — גישה וזהות",'הערכת סיכונים'!$W$3:$W$74,"לא"),0)
A45: הגנה — רשת ותשתית | B45: =COUNTIFS('הערכת סיכונים'!$B$3:$B$74,"הגנה — רשת ותשתית",'הערכת סיכונים'!$W$3:$W$74,"לא") | C45: =COUNTIFS('הערכת סיכונים'!$B$3:$B$74,"הגנה — רשת ותשתית",'הערכת סיכונים'!$S$3:$S$74,"קריטי",'הערכת סיכונים'!$W$3:$W$74,"לא") | D45: =COUNTIFS('הערכת סיכונים'!$B$3:$B$74,"הגנה — רשת ותשתית",'הערכת סיכונים'!$S$3:$S$74,"גבוה",'הערכת סיכונים'!$W$3:$W$74,"לא") | E45: =IFERROR(AVERAGEIFS('הערכת סיכונים'!$J$3:$J$74,'הערכת סיכונים'!$B$3:$B$74,"הגנה — רשת ותשתית",'הערכת סיכונים'!$W$3:$W$74,"לא",'הערכת סיכונים'!$J$3:$J$74,">0"),0) | F45: =IFERROR(AVERAGEIFS('הערכת סיכונים'!$R$3:$R$74,'הערכת סיכונים'!$B$3:$B$74,"הגנה — רשת ותשתית",'הערכת סיכונים'!$W$3:$W$74,"לא",'הערכת סיכונים'!$R$3:$R$74,">0"),0) | G45: =IFERROR(AVERAGEIFS('הערכת סיכונים'!$Z$3:$Z$74,'הערכת סיכונים'!$B$3:$B$74,"הגנה — רשת ותשתית",'הערכת סיכונים'!$W$3:$W$74,"לא"),0)
...
