Workbook

Sheet ראשי
A2: 1. בחר מאגר דפאות/תרחישים עבור הסקר. ניתן להיעזר בגיליונות שבמסמך זה או במאגר חלופי
A3: 2. הגדר מתוך כלל האיומים והתרחישים, את האיומים לייחוס
A4: 3. עבור כל איום, הגדר סבירות ועוצמה
A5: 4. הגדר אופן טיפול באיומים בהתאם לתיאבון הסיכון
A6: 5. הגדר בקרות מפצות וצעדים נוספים להפחתת הסיכון מתוך גיליון בקרות, או מתוך מאגר בקרות חלופי

Sheet דפאות בסיסי
A1: מקור | B1: תיאור | C1: הממשק
A2: איום פנימי | B2: שליחת הודעת דוא"ל עם מידע ארגוני לגורם לא מורשה | C2: דוא"ל
A3: איום פנימי | B3: טעינת קובץ עם מידע ארגוני לאתר חיצוני שאינו מורשה (דוא"ל, BOX וכו') | C3: גישה לאינטרנט
A4: איום פנימי | B4: העתקה ללא רשות של מידע ארגוני להתקן חיצוני (לרבות קוד מקור) | C4: התקן חיצוני (DOK, CD etc.)
A5: איום פנימי | B5: גישה למידע ארגוני (דיגיטלי/פיזי) ללא רשות | C5: גישה פיזית או גישה רשתית (כגון גישה מרחוק או שיטוט בתיקיות רשת)
A6: איום פנימי | B6: התקנת תוכנה לא מורשית / תוכנה עם נוזקה | C6: עמדת עבודה, גישה רשתית
A7: איום פנימי | B7: חשיפת מידע ארגוני בפני לא מורשה (פישינג, שיחת חולין וכו') | C7: גישה לאינטרנט, גישה פיזית
A8: איום פנימי | B8: חיבור התקן חיצוני עם נוזקה לרשת הארגון | C8: התקן חיצוני (דוגמת DOK, CD)
A9: איום פנימי | B9: מחיקה/שיבוש/מניעת גישה למידע ארגוני | C9: עמדת עבודה, גישה רשתית
A10: איום פנימי | B10: גניבה פיסית או אובדן של התקן/רכיב מחשוב | C10: גישה פיזית
A11: איום פנימי | B11: גניבה פיסית או אובדן של מסמך מודפס המכיל מידע ארגוני | C11: גישה פיזית
A12: איום חיצוני | B12: מניעת שירות במבואות האינטרנט של הארגון | C12: גישה לאינטרנט
... A34: שרשרת אספקה | B34: פיתוח מוצר תוכנה עבור הארגון המכיל חולשות מהותיות המנוצלות לרעה (דוגמת Back door) | C34: גישה רשתית

Sheet דפאות מורחב
A1: חלופה בסיסית | B1: משפחה/דפ"א | C1: תת משפחה/דפ"א | D1: האיום | E1: אופן מימוש | F1: ממשק ביצוע | G1: קושי מימוש התרחיש 1(H)-2(M)-3(L) | H1: מידת נפוצות התרחיש 1(L)-2(M)-3(H) | I1: חלופה מתקדמת | J1: # | K1: =IFERROR(__xludf.DUMMYFUNCTION("GOOGLETRANSLATE(B2, ""auto"", ""en"")"),"Name UBI") -> Name UBI | L1: =IFERROR(__xludf.DUMMYFUNCTION("GOOGLETRANSLATE(D2, ""auto"", ""en"")"),"Description") -> Description | M1: =IFERROR(__xludf.DUMMYFUNCTION("GOOGLETRANSLATE(F2, ""auto"", ""en"")"),"Source threat (characteristics and potential of the offender)") -> Source threat (characteristics and potential of the offender) | N1: =IFERROR(__xludf.DUMMYFUNCTION("GOOGLETRANSLATE(H2, ""auto"", ""en"")"),"the impact of an object") -> the impact of an object
B2: מחשוב ענן ציבורי | C2: ניצול הרשאות עובד פנימי/חיצוני | D2: איום חיצוני/שרשרת אספקה | E2: ניצול שירותי ענן חיצונים של החברה על מנת להוציא מידע סודי וזאת ע"י עובדי ספק הענן עצמו ואו באמצעותם | F2: גישה מרחוק, גישה רשתית | G2: 2 | H2: 2 | J2: 1 | K2: =IFERROR(__xludf.DUMMYFUNCTION("GOOGLETRANSLATE(B3, ""auto"", ""en"")"),"The threat of the automatic propagation of malicious code into a grid system") -> The threat of the automatic propagation of malicious code into a grid system | L2: =IFERROR(__xludf.DUMMYFUNCTION("GOOGLETRANSLATE(D3, ""auto"", ""en"")"),"The threat is the ability to implement and run malicious code on behalf of a trusted process in any of the resource grid system of centers and its automatic extension to all nodes of grid system. This threat is caused by weakness of grid computing techno"&"logy - a high level of automation at low manageability grid system. Implementation of this threat can be provided that the offender is a legal privilege user grid system") -> The threat is the ability to implement and run malicious code on behalf of a trusted process in any of the resource grid system of centers and its automatic extension to all nodes of grid system. This threat is caused by weakness of grid computing technology - a high level of automation at low manageability grid system. Implementation of this threat can be provided that the offender is a legal privilege user grid system | M2: =IFERROR(__xludf.DUMMYFUNCTION("GOOGLETRANSLATE(F3, ""auto"", ""en"")"),"External intruder with an average potential intruder inner middle potential") -> External intruder with an average potential intruder inner middle potential | N2: =IFERROR(__xludf.DUMMYFUNCTION("GOOGLETRANSLATE(H3, ""auto"", ""en"")"),"Resource Centers grid system") -> Resource Centers grid system
B3: הגנה על המידע | C3: אגירת מידע רגיש | D3: איום פנימי | E3: שליחת מידע עסקי (תכניות אסטרטגיות, סודות מסחריים, גורמים חיצוניים, לקוחות, שותפים עסקיים וכו') לכתובת מייל פרטית | F3: גישה לאינטרנט (גלישה, דוא"ל וכו') | G3: 3 | H3: 3 | J3: 2 | K3: =IFERROR(__xludf.DUMMYFUNCTION("GOOGLETRANSLATE(B4, ""auto"", ""en"")"),"The threat of aggregating data transmitted in the Grid System") -> The threat of aggregating data transmitted in the Grid System | L3: =IFERROR(__xludf.DUMMYFUNCTION("GOOGLETRANSLATE(D4, ""auto"", ""en"")"),"The threat is the possibility of the disclosure of information protected by intruder detection involved in its processing units, data collection, analysis and synthesis of data intercepted by the data transmission network grid system. This threat is caus"&"ed by the weakness of grid computing technology - the use of unprotected Internet channel as a transport network grid system. Implementation of this threat can be provided that the offender: forces and sufficient funds to compensate for the distributed "&"emergency Grid assignments between nodes grid system; privileges sufficient to intercept the data traffic between the network elements (nodes) grid system") -> The threat is the possibility of the disclosure of information protected by intruder detection involved in its processing units, data collection, analysis and synthesis of data intercepted by the data transmission network grid system. This threat is caused by the weakness of grid computing technology - the use of unprotected Internet channel as a transport network grid system. Implementation of this threat can be provided that the offender: forces and sufficient funds to compensate for the distributed emergency Grid assignments between nodes grid system; privileges sufficient to intercept the data traffic between the network elements (nodes) grid system | M3: =IFERROR(__xludf.DUMMYFUNCTION("GOOGLETRANSLATE(F4, ""auto"", ""en"")"),"The outer middle potential violator") -> The outer middle potential violator | N3: =IFERROR(__xludf.DUMMYFUNCTION("GOOGLETRANSLATE(H4, ""auto"", ""en"")"),"network traffic") -> network traffic
B4: הגנת תחנות עבודה ושרתים | C4: חדירה מהאינטרנט ישירות לרשת הארגון | D4: איום פנימי/חיצוני | E4: חיבור ציוד מחשב לעמדת קצה ואו לעמדה/רשת מבודלת עם רגל החוצה לאינטרנט באמצעות: הקמת HOT SPOT ואו רשת אלחוטית | F4: התקן חיצוני (דוגמת LAPTOP, WIFI) | G4: 3 | H4: 3 | J4: 3 | K4: =IFERROR(__xludf.DUMMYFUNCTION("GOOGLETRANSLATE(B5, ""auto"", ""en"")"),"cryptographic algorithms to analyze the threat and their implementation") -> cryptographic algorithms to analyze the threat and their implementation | L4: =IFERROR(__xludf.DUMMYFUNCTION("GOOGLETRANSLATE(D5, ""auto"", ""en"")"),"The threat is the ability to identify weaknesses in the cryptographic algorithms, or vulnerabilities in the software that implements them. This threat is due to weaknesses of cryptographic algorithms, as well as errors in the program code of cryptographi"&"c tools, their conjugation with the system or their settings. Implementation of the threat is possible in the case of the offender information on the means used in the encryption system implemented in their encryption algorithms and their settings") -> The threat is the ability to identify weaknesses in the cryptographic algorithms, or vulnerabilities in the software that implements them. This threat is due to weaknesses of cryptographic algorithms, as well as errors in the program code of cryptographic tools, their conjugation with the system or their settings. Implementation of the threat is possible in the case of the offender information on the means used in the encryption system implemented in their encryption algorithms and their settings | M4: =IFERROR(__xludf.DUMMYFUNCTION("GOOGLETRANSLATE(F5, ""auto"", ""en"")"),"The outer middle potential violator") -> The outer middle potential violator | N4: =IFERROR(__xludf.DUMMYFUNCTION("GOOGLETRANSLATE(H5, ""auto"", ""en"")"),"Metadata, system software") -> Metadata, system software
B5: הגנה על המידע | C5: אגירת מידע רגיש | D5: איום פנימי | E5: אגירת המידע טרם הזלגתו - במערכת, ברשומות, במדיה חיצונית | F5: התקן חיצוני (דוגמת DOK, CD) | G5: 3 | H5: 2 | J5: 4 | K5: =IFERROR(__xludf.DUMMYFUNCTION("GOOGLETRANSLATE(B6, ""auto"", ""en"")"),"Threat hardware reset BIOS password") -> Threat hardware reset BIOS password | L5: =IFERROR(__xludf.DUMMYFUNCTION("GOOGLETRANSLATE(D6, ""auto"", ""en"")"),"The threat is reset passwords capabilities installed in BIOS / UEFI without passing authorization procedure in the system by de-energizing BIOS chip (accumulator material removal) or install jumpers in the normal place on the system board (switch ""jumper"&"""). This threat is due to some system vulnerabilities (parent) boards - the presence of hard reset passwords mechanisms installed in BIOS / UEFI. Implementation of this threat is possible on condition that the intruder physical access to the computer s"&"ystem unit") -> The threat is reset passwords capabilities installed in BIOS / UEFI without passing authorization procedure in the system by de-energizing BIOS chip (accumulator material removal) or install jumpers in the normal place on the system board (switch "jumper"). This threat is due to some system vulnerabilities (parent) boards - the presence of hard reset passwords mechanisms installed in BIOS / UEFI. Implementation of this threat is possible on condition that the intruder physical access to the computer system unit | M5: =IFERROR(__xludf.DUMMYFUNCTION("GOOGLETRANSLATE(F6, ""auto"", ""en"")"),"Insider with a low potential") -> Insider with a low potential | N5: =IFERROR(__xludf.DUMMYFUNCTION("GOOGLETRANSLATE(H6, ""auto"", ""en"")"),"Firmware and BIOS / UEFI hardware") -> Firmware and BIOS / UEFI hardware
B6: הגנה על המידע | C6: ניצול הרשאות עובד פנימי/חיצוני | D6: שרשרת אספקה | E6: שימוש בתהליך לגיטימי של מערכת מחשב שמוציא מידע החוצה לאינטרנט ועליו לייצא מידע נוסף שאינו רלוונטי לפעולה הנדרשת | F6: גישה לאינטרנט | G6: 1 | H6: 1 | J6: 5 | K6: =IFERROR(__xludf.DUMMYFUNCTION("GOOGLETRANSLATE(B7, ""auto"", ""en"")"),"The threat of malicious code in the BIOS") -> The threat of malicious code in the BIOS | L6: =IFERROR(__xludf.DUMMYFUNCTION("GOOGLETRANSLATE(D7, ""auto"", ""en"")"),"The threat is the ability to make the BIOS / UEFI execute malicious code each time the computer is started by introducing it into the BIOS / UEFI chips by replacing BIOS / UEFI or update BIOS / UEFI software to a version that already contains malicious co"&"de. This threat is due to the weaknesses of control technologies for updating BIOS / UEFI software and BIOS / UEFI replacement chipset. Implementation of this threat is possible in the course of repair and computer maintenance") -> The threat is the ability to make the BIOS / UEFI execute malicious code each time the computer is started by introducing it into the BIOS / UEFI chips by replacing BIOS / UEFI or update BIOS / UEFI software to a version that already contains malicious code. This threat is due to the weaknesses of control technologies for updating BIOS / UEFI software and BIOS / UEFI replacement chipset. Implementation of this threat is possible in the course of repair and computer maintenance | M6: =IFERROR(__xludf.DUMMYFUNCTION("GOOGLETRANSLATE(F7, ""auto"", ""en"")"),"Insider with high potential") -> Insider with high potential | N6: =IFERROR(__xludf.DUMMYFUNCTION("GOOGLETRANSLATE(H7, ""auto"", ""en"")"),"Firmware and BIOS / UEFI hardware") -> Firmware and BIOS / UEFI hardware
B7: אבטחת רשת | C7: ניצול הרשאות עובד פנימי/חיצוני | D7: איום פנימי | E7: התקנה ושימוש בתוכנות שיתוף קבצים | F7: גישה לאינטרנט | G7: 3 | H7: 2 | J7: 6 | K7: =IFERROR(__xludf.DUMMYFUNCTION("GOOGLETRANSLATE(B8, ""auto"", ""en"")"),"code injection, or threat data") -> code injection, or threat data | L7: =IFERROR(__xludf.DUMMYFUNCTION("GOOGLETRANSLATE(D8, ""auto"", ""en"")"),"The threat is the possibility of the introduction of the offender in diskreditiruemuyu information or IoT-device malicious code, which can be launched in the future ""by hand"" users automatically when performing certain conditions (occurrence of a certai"&"n date, user logon, etc.) or using the authentication data set ""by default"", as well as the possibility of the introduction of unauthorized intruder some proprietary data to be processed in an information system diskreditiruemuyu actually having carried"&" out the illegal use of other people's computer resources, and block devices work when certain commands. This threat is caused by: presence of software vulnerabilities; weaknesses measures antivirus and access control; Telnet-presence of open ports on"&" IoT-device (for IoT-devices). The implementation of this possible threat: in the case of diskreditiruemogo user with files coming from untrusted sources; if he has privileges install the software; in the case of unmodified owner credentials IoT-devic"&"e (factory password and login)") -> The threat is the possibility of the introduction of the offender in diskreditiruemuyu information or IoT-device malicious code, which can be launched in the future "by hand" users automatically when performing certain conditions (occurrence of a certain date, user logon, etc.) or using the authentication data set "by default", as well as the possibility of the introduction of unauthorized intruder some proprietary data to be processed in an information system diskreditiruemuyu actually having carried out the illegal use of other people's computer resources, and block devices work when certain commands. This threat is caused by: presence of software vulnerabilities; weaknesses measures antivirus and access control; Telnet-presence of open ports on IoT-device (for IoT-devices). The implementation of this possible threat: in the case of diskreditiruemogo user with files coming from untrusted sources; if he has privileges install the software; in the case of unmodified owner credentials IoT-device (factory password and login) | M7: =IFERROR(__xludf.DUMMYFUNCTION("GOOGLETRANSLATE(F8, ""auto"", ""en"")"),"External intruder with a low potential") -> External intruder with a low potential | N7: =IFERROR(__xludf.DUMMYFUNCTION("GOOGLETRANSLATE(H8, ""auto"", ""en"")"),"System software, application software, networking software") -> System software, application software, networking software
B8: הגנה על המידע | C8: רשלנות מקצועית | D8: איום פנימי | E8: איבוד/הוצאה של מדיה, רשומות פיזיות ורכיבי מחשוב עם מידע מסווג, אל מחוץ למתקן והגעתם אל גורם עוין | F8: גישה פיזית | G8: 3 | H8: 3 | J8: 7 | K8: =IFERROR(__xludf.DUMMYFUNCTION("GOOGLETRANSLATE(B9, ""auto"", ""en"")"),"The threat of exposure to the program with high privileges") -> The threat of exposure to the program with high privileges | L8: =IFERROR(__xludf.DUMMYFUNCTION("GOOGLETRANSLATE(D9, ""auto"", ""en"")"),"The threat is the possibility of increasing the offender of their privileges in the discredited system (getting discredited programs privileges) through the use of bugs in the programs and execute arbitrary code with their privileges. This threat is caus"&"ed by input validation weaknesses mechanism and teams, as well as the delimitation of access measures. Implementation of this threat is possible under the conditions: possession diskreditiruemoy program elevated privileges on the system; diskreditiruem"&"oy of the program receiving input from other programs or from the user; the offender is able to transmit data to the program diskreditiruemoy") -> The threat is the possibility of increasing the offender of their privileges in the discredited system (getting discredited programs privileges) through the use of bugs in the programs and execute arbitrary code with their privileges. This threat is caused by input validation weaknesses mechanism and teams, as well as the delimitation of access measures. Implementation of this threat is possible under the conditions: possession diskreditiruemoy program elevated privileges on the system; diskreditiruemoy of the program receiving input from other programs or from the user; the offender is able to transmit data to the program diskreditiruemoy | M8: =IFERROR(__xludf.DUMMYFUNCTION("GOOGLETRANSLATE(F9, ""auto"", ""en"")"),"External intruder with an average potential intruder inner middle potential") -> External intruder with an average potential intruder inner middle potential | N8: =IFERROR(__xludf.DUMMYFUNCTION("GOOGLETRANSLATE(H9, ""auto"", ""en"")"),"Information system, virtual machine, network software, network traffic") -> Information system, virtual machine, network software, network traffic
B9: הגנה על המידע | C9: רשלנות מקצועית | D9: שרשרת אספקה | E9: הוצאה של רשומות גרוסות עם מידע מסווג, אל מחוץ למתקן והגעתם אל גורם עוין | F9: גישה פיזית | G9: 3 | H9: 2 | J9: 8 | K9: =IFERROR(__xludf.DUMMYFUNCTION("GOOGLETRANSLATE(B10, ""auto"", ""en"")"),"The threat of recovery and / or reuse of the authentication information") -> The threat of recovery and / or reuse of the authentication information | L9: =IFERROR(__xludf.DUMMYFUNCTION("GOOGLETRANSLATE(D10, ""auto"", ""en"")"),"The threat lies in the possibility of access to user data as a result of the selection (e.g. by exhaustive search or sorting dictionary) diskreditiruemoy authentication information with the user account in the system, as well as by intercepting and re-use"&" password hash to recover the session. This threat is due to the following disadvantages: much smaller volume of data authentication information hash code compared with itself (the time of selection of the hash codes is less than the exhaustive search t"&"ime of authentication information); weaknesses in the algorithm for calculating a hash code, prevent its re-use to perform a successful authentication. Implementation of this threat is possible with the help of special software, and in some cases - ""ma"&"nually""") -> The threat lies in the possibility of access to user data as a result of the selection (e.g. by exhaustive search or sorting dictionary) diskreditiruemoy authentication information with the user account in the system, as well as by intercepting and re-use password hash to recover the session. This threat is due to the following disadvantages: much smaller volume of data authentication information hash code compared with itself (the time of selection of the hash codes is less than the exhaustive search time of authentication information); weaknesses in the algorithm for calculating a hash code, prevent its re-use to perform a successful authentication. Implementation of this threat is possible with the help of special software, and in some cases - "manually" | M9: =IFERROR(__xludf.DUMMYFUNCTION("GOOGLETRANSLATE(F10, ""auto"", ""en"")"),"External intruder low potential insider with a low potential") -> External intruder low potential insider with a low potential | N9: =IFERROR(__xludf.DUMMYFUNCTION("GOOGLETRANSLATE(H10, ""auto"", ""en"")"),"System software, firmware, usernames user data") -> System software, firmware, usernames user data
B10: הגנה פיזית וסביבתית | C10: הנדסה חברתית לעובד פנימי/חיצוני | D10: איום פנימי/חיצוני | E10: שיטוי והתקנת רכיבי ריגול במתחם מסווג באמצעות הטמנת אמצעי האזנה/הקלטה/שידור | F10: גישה פיזית | G10: 1 | H10: 1 | J10: 9 | K10: =IFERROR(__xludf.DUMMYFUNCTION("GOOGLETRANSLATE(B11, ""auto"", ""en"")"),"Threat to restore the previous version of the BIOS vulnerable") -> Threat to restore the previous version of the BIOS vulnerable | L10: =IFERROR(__xludf.DUMMYFUNCTION("GOOGLETRANSLATE(D11, ""auto"", ""en"")"),"The threat lies in the possibility of the use of the stimulated transition BIOS / UEFI, comprising vulnerability. This threat is due to the weaknesses of control technologies for updating BIOS / UEFI software. When using the BIOS / UEFI technology updat"&"es, you may experience the following situation (conditions that characterize the situation listed in chronological order): the computer is running some version of BIOS / UEFI, for which at the time of its operation are not known vulnerabilities; due to "&"certain BIOS / UEFI circumstances runs the update process by maintaining the previous BIOS / UEFI version in the case of a ""rollback"" of the system; published data on the existence of vulnerabilities in previous versions of BIOS / UEFI; malfunction oc"&"curs in the system, whereby the current (new) version of the BIOS / UEFI becomes inoperative (e.g., its integrity is violated); the user carries out a full-time system recovery procedure - conducting a ""rollback"" of the system to a previous working sta"&"te") -> The threat lies in the possibility of the use of the stimulated transition BIOS / UEFI, comprising vulnerability. This threat is due to the weaknesses of control technologies for updating BIOS / UEFI software. When using the BIOS / UEFI technology updates, you may experience the following situation (conditions that characterize the situation listed in chronological order): the computer is running some version of BIOS / UEFI, for which at the time of its operation are not known vulnerabilities; due to certain BIOS / UEFI circumstances runs the update process by maintaining the previous BIOS / UEFI version in the case of a "rollback" of the system; published data on the existence of vulnerabilities in previous versions of BIOS / UEFI; malfunction occurs in the system, whereby the current (new) version of the BIOS / UEFI becomes inoperative (e.g., its integrity is violated); the user carries out a full-time system recovery procedure - conducting a "rollback" of the system to a previous working state | M10: =IFERROR(__xludf.DUMMYFUNCTION("GOOGLETRANSLATE(F11, ""auto"", ""en"")"),"Insider with a low potential") -> Insider with a low potential | N10: =IFERROR(__xludf.DUMMYFUNCTION("GOOGLETRANSLATE(H11, ""auto"", ""en"")"),"BIOS / UEFI firmware") -> BIOS / UEFI firmware
B11: אבטחה ברכש ופיתוח | C11: חבלה בשרשרת אספקה | D11: איום פנימי/חיצוני | E11: התקנת/החלפת מוצר/ציוד המוגדר כ"מטופל" ע"י גורם פנימי ואו חיצוני - לצרכי האזנה או לחדירה מרחוק לרשת, חוסר מודעות, רשלנות מקצועית, חוסר משמעת ואו עובד ממורמר. ה"טיפול" יכול להתבצע לאורך כל שרשרת האספקה ואו התפעול: פיתוח, ייצור, משלוח, המתנה אצל ספק משנה, התקנה בלקוח, עדכוני חתימות, מפתחות הצפנה ותוכנה, תחזוקה, שליחה לתיקון וביצוע מבדקים (חדירה, פגיעויות, פורנזיקה וביקורת) | F11: גישה פיזית, גישה רשתית, גישה מרחוק | G11: 3 | H11: 2 | J11: 10 | K11: =IFERROR(__xludf.DUMMYFUNCTION("GOOGLETRANSLATE(B12, ""auto"", ""en"")"),"process exit threat of the virtual machine") -> process exit threat of the virtual machine | L11: =IFERROR(__xludf.DUMMYFUNCTION("GOOGLETRANSLATE(D12, ""auto"", ""en"")"),"The threat is the ability to run the malicious program's own hypervisor, operating on the level of logical interaction below being compromised hypervisor. This threat is caused by software vulnerabilities hypervisor that implements the function of the sa"&"ndbox for operating in its programs, as well as weaknesses in hardware support for virtualization at the processor level instructions. Implementation of this threat leads not only to compromise the hypervisor, but running in a virtual environment created"&" by him protection and, consequently, to their inability to perform security functions for malware, operating under the control of its own hypervisor") -> The threat is the ability to run the malicious program's own hypervisor, operating on the level of logical interaction below being compromised hypervisor. This threat is caused by software vulnerabilities hypervisor that implements the function of the sandbox for operating in its programs, as well as weaknesses in hardware support for virtualization at the processor level instructions. Implementation of this threat leads not only to compromise the hypervisor, but running in a virtual environment created by him protection and, consequently, to their inability to perform security functions for malware, operating under the control of its own hypervisor | M11: =IFERROR(__xludf.DUMMYFUNCTION("GOOGLETRANSLATE(F12, ""auto"", ""en"")"),"External intruder with an average potential intruder inner middle potential") -> External intruder with an average potential intruder inner middle potential | N11: =IFERROR(__xludf.DUMMYFUNCTION("GOOGLETRANSLATE(H12, ""auto"", ""en"")"),"Information System, a network node, the media, the file system object, Accounts user data, virtual machine image") -> Information System, a network node, the media, the file system object, Accounts user data, virtual machine image
B12: הגנה על המידע | C12: רשלנות מקצועית | D12: איום פנימי | E12: ציתות לשיחות קוליות מסווגות בשל קירבה פיזית ואו בזמן ששיחה טלפונית אחרת מתקיימת ברקע | F12: גישה פיזית, גישה טלפונית | G12: 3 | H12: 2 | J12: 11 | K12: =IFERROR(__xludf.DUMMYFUNCTION("GOOGLETRANSLATE(B13, ""auto"", ""en"")"),"Threat deauthorize authorized wireless client") -> Threat deauthorize authorized wireless client | L12: =IFERROR(__xludf.DUMMYFUNCTION("GOOGLETRANSLATE(D13, ""auto"", ""en"")"),"The threat is the possibility of automatic disconnection of the wireless access point to authorized wireless client. This threat is caused by the weakness of networking technology for wireless data communication channels - information about the MAC addre"&"sses of wireless clients available to all participants in networking. Implementation of this threat can be provided to connect the violator to a wireless network device, the MAC address will be the same as the MAC address of the client's authorized diskr"&"editiruemogo") -> The threat is the possibility of automatic disconnection of the wireless access point to authorized wireless client. This threat is caused by the weakness of networking technology for wireless data communication channels - information about the MAC addresses of wireless clients available to all participants in networking. Implementation of this threat can be provided to connect the violator to a wireless network device, the MAC address will be the same as the MAC address of the client's authorized diskreditiruemogo | M12: =IFERROR(__xludf.DUMMYFUNCTION("GOOGLETRANSLATE(F13, ""auto"", ""en"")"),"External intruder low potential insider with a low potential") -> External intruder low potential insider with a low potential | N12: =IFERROR(__xludf.DUMMYFUNCTION("GOOGLETRANSLATE(H13, ""auto"", ""en"")"),"The network node") -> The network node
B13: הגנה פיזית וסביבתית | C13: ניצול הרשאות עובד פנימי/חיצוני | D13: איום חיצוני/שרשרת אספקה | E13: נגישות לנקודה חמה ואו תווך/ציוד תקשורת אשר אליו מחוברות מערכות הארגון ופתיחת קו החוצה | F13: גישה פיזית, גישה רשתית | G13: 2 | H13: 3 | J13: 12 | K13: =IFERROR(__xludf.DUMMYFUNCTION("GOOGLETRANSLATE(B14, ""auto"", ""en"")"),"The threat of a destructive change of configuration / programming environment protection") -> The threat of a destructive change of configuration / programming environment protection | L13: =IFERROR(__xludf.DUMMYFUNCTION("GOOGLETRANSLATE(D14, ""auto"", ""en"")"),"The threat is the possibility of a destructive impact on the software application diskreditiruemoe way of manipulation with the configuration files or libraries used them. This threat is caused by weakness of integrity controls configuration files or lib"&"raries used by applications. Implementation of this threat is possible in the case of the infringer of the rights of the entries in the file objects associated with the configuration / software environment environment, or the ability to redirect requests"&" from the program diskreditiruemoy protected file object to false") -> The threat is the possibility of a destructive impact on the software application diskreditiruemoe way of manipulation with the configuration files or libraries used them. This threat is caused by weakness of integrity controls configuration files or libraries used by applications. Implementation of this threat is possible in the case of the infringer of the rights of the entries in the file objects associated with the configuration / software environment environment, or the ability to redirect requests from the program diskreditiruemoy protected file object to false | M13: =IFERROR(__xludf.DUMMYFUNCTION("GOOGLETRANSLATE(F14, ""auto"", ""en"")"),"Insider with a low potential") -> Insider with a low potential | N13: =IFERROR(__xludf.DUMMYFUNCTION("GOOGLETRANSLATE(H14, ""auto"", ""en"")"),"System software, application software, network software, firmware, metadata, file system objects, the registry") -> System software, application software, network software, firmware, metadata, file system objects, the registry
B14: הגנת תחנות עבודה ושרתים | C14: ניצול הרשאות עובד פנימי/חיצוני | D14: איום פנימי/חיצוני | E14: נגישות לעמדת קצה של משתמש (כולל מכשיר סלולרי) והתקנת כלי הסנפה/תקיפה/השתלטות ואו הטמנת קוד, שינוי הגדרות מערכת, שאיבת מידע עם מדיה חיצונית ואו שימוש בהרשאות הלגיטימיות של המשתמש במערכות הארגון ואו ליצור חשבונות נוספים כדי לחדור למערכות. במידה והעמדה אינה מחוברת לאינטרנט תיתכן התקנת ACCESS POINT והמשך דפ"א בהתאם לעיל | F14: גישה פיזית, גישה רשתית, גישה מרחוק | G14: 2 | H14: 3 | J14: 13 | K14: =IFERROR(__xludf.DUMMYFUNCTION("GOOGLETRANSLATE(B15, ""auto"", ""en"")"),"The threat of a destructive use of the declared functional BIOS") -> The threat of a destructive use of the declared functional BIOS | L14: =IFERROR(__xludf.DUMMYFUNCTION("GOOGLETRANSLATE(D15, ""auto"", ""en"")"),"The threat is the possibility of misuse declared BIOS / UEFI functional for violating the integrity of the information stored in the external storage media and a random access memory computer. This threat is caused by vulnerabilities BIOS / UEFI software"&" designed for testing and computer maintenance (funds check memory integrity, software RAID-controller management software, etc.). Realization of this threat may contribute to the ability to update some of the BIOS / UEFI without passing authentication") -> The threat is the possibility of misuse declared BIOS / UEFI functional for violating the integrity of the information stored in the external storage media and a random access memory computer. This threat is caused by vulnerabilities BIOS / UEFI software designed for testing and computer maintenance (funds check memory integrity, software RAID-controller management software, etc.). Realization of this threat may contribute to the ability to update some of the BIOS / UEFI without passing authentication | M14: =IFERROR(__xludf.DUMMYFUNCTION("GOOGLETRANSLATE(F15, ""auto"", ""en"")"),"Insider with a low potential") -> Insider with a low potential | N14: =IFERROR(__xludf.DUMMYFUNCTION("GOOGLETRANSLATE(H15, ""auto"", ""en"")"),"BIOS / UEFI firmware") -> BIOS / UEFI firmware
B15: בקרת גישה | C15: רשלנות מקצועית | D15: איום פנימי | E15: הצצה למחשבים/רשומות מסווגות | F15: גישה פיזית | G15: 3 | H15: 3 | J15: 14 | K15: =IFERROR(__xludf.DUMMYFUNCTION("GOOGLETRANSLATE(B16, ""auto"", ""en"")"),"The threat of long-term retention of the user's computing resources") -> The threat of long-term retention of the user's computing resources | L15: =IFERROR(__xludf.DUMMYFUNCTION("GOOGLETRANSLATE(D16, ""auto"", ""en"")"),"The threat is the possibility of limiting the infringer end-user access to computing resources at the expense of his forced confinement in a loaded state by repeatedly performing the exercise of certain destructive action or operation, distributing comput"&"ing resources among tasks for application vulnerabilities. This threat is caused by weaknesses load balancing and allocation of computing resources. Implementation of the threat is possible if the offender has the opportunity to make requests, all of wh"&"ich require more time to complete than the user requests") -> The threat is the possibility of limiting the infringer end-user access to computing resources at the expense of his forced confinement in a loaded state by repeatedly performing the exercise of certain destructive action or operation, distributing computing resources among tasks for application vulnerabilities. This threat is caused by weaknesses load balancing and allocation of computing resources. Implementation of the threat is possible if the offender has the opportunity to make requests, all of which require more time to complete than the user requests | M15: =IFERROR(__xludf.DUMMYFUNCTION("GOOGLETRANSLATE(F16, ""auto"", ""en"")"),"External intruder low potential insider with a low potential") -> External intruder low potential insider with a low potential | N15: =IFERROR(__xludf.DUMMYFUNCTION("GOOGLETRANSLATE(H16, ""auto"", ""en"")"),"Information System, a network node, data carrier, system software, network software, network traffic") -> Information System, a network node, data carrier, system software, network software, network traffic
B16: אבטחת רשת | C16: שיבוש/השבתת שירותים | D16: איום חיצוני | E16: מניעת גישה למידע ואו שירות באתר אינטרנט באמצעות השבתת הרכיב על ידי מתקפת DDOS | F16: גישה פיזית, גישה ידי | G16: 2 | H16: 3 | J16: 15 | K16: =IFERROR(__xludf.DUMMYFUNCTION("GOOGLETRANSLATE(B17, ""auto"", ""en"")"),"The threat of access to protected files using the workaround") -> The threat of access to protected files using the workaround | L16: =IFERROR(__xludf.DUMMYFUNCTION("GOOGLETRANSLATE(D17, ""auto"", ""en"")"),"The threat is the possibility of obtaining the offender access to the hidden / protected folders or files through various actions on the file system (to add additional characters to specify a file path, accessing files that are not explicitly listed in th"&"e application window). This threat is due to the weaknesses of the mechanism of differentiation of access to file system objects. Implementation of this threat is possible under the conditions: the presence of the violator of the rights of access to ce"&"rtain file system objects; lack of verification data entered by the user; possession diskreditiruemoy program too high privilege access to the files, the processing of which is not intended to help her") -> The threat is the possibility of obtaining the offender access to the hidden / protected folders or files through various actions on the file system (to add additional characters to specify a file path, accessing files that are not explicitly listed in the application window). This threat is due to the weaknesses of the mechanism of differentiation of access to file system objects. Implementation of this threat is possible under the conditions: the presence of the violator of the rights of access to certain file system objects; lack of verification data entered by the user; possession diskreditiruemoy program too high privilege access to the files, the processing of which is not intended to help her | M16: =IFERROR(__xludf.DUMMYFUNCTION("GOOGLETRANSLATE(F17, ""auto"", ""en"")"),"External intruder low potential insider with a low potential") -> External intruder low potential insider with a low potential | N16: =IFERROR(__xludf.DUMMYFUNCTION("GOOGLETRANSLATE(H17, ""auto"", ""en"")"),"File System Objects") -> File System Objects
B17: שרשרת אספקה ומיקור חוץ | C17: פרסום מידע סודי/שגוי | D17: איום פנימי | E17: הפצת מידע עסקי, פנימי ואו כוזב באתר אינטרנט (תכניות אסטרטגיות, סודות מסחריים, גורמים חיצוניים, לקוחות, שותפים עסקיים וכו') | F17: גישה פיזית, גישה שותפים | G17: 2 | H17: 1 | J17: 16 | K17: =IFERROR(__xludf.DUMMYFUNCTION("GOOGLETRANSLATE(B18, ""auto"", ""en"")"),"The threat of access to local files on the server using the URL") -> The threat of access to local files on the server using the URL | L17: =IFERROR(__xludf.DUMMYFUNCTION("GOOGLETRANSLATE(D18, ""auto"", ""en"")"),"The threat is the possibility of transfer of the offender diskreditiruemomu browser request for access to the file system user instead of URL-request. In this browser execute this request to the rights that he is endowed with at startup, and transmit data"&" obtained as a result of this operation, the violator. This threat is caused by weaknesses introduced by the user requests a verification mechanism, which does not distinguish between requests for access to the file system, and URL-requests. Implementat"&"ion of this threat is possible in the case of the offender privileges to send a browser request, the system operates in diskreditiruemoy") -> The threat is the possibility of transfer of the offender diskreditiruemomu browser request for access to the file system user instead of URL-request. In this browser execute this request to the rights that he is endowed with at startup, and transmit data obtained as a result of this operation, the violator. This threat is caused by weaknesses introduced by the user requests a verification mechanism, which does not distinguish between requests for access to the file system, and URL-requests. Implementation of this threat is possible in the case of the offender privileges to send a browser request, the system operates in diskreditiruemoy | M17: =IFERROR(__xludf.DUMMYFUNCTION("GOOGLETRANSLATE(F18, ""auto"", ""en"")"),"The outer middle potential violator") -> The outer middle potential violator | N17: =IFERROR(__xludf.DUMMYFUNCTION("GOOGLETRANSLATE(H18, ""auto"", ""en"")"),"Networking software") -> Networking software
B18: הגנה על המידע | C18: האזנה לסניף בחו"ל מול המטה בישראל | D18: איום חיצוני | E18: נגישות לנתונים של הארגון אשר עוברים בתווך בינ"ל מול המערכות בסניף בחו"ל. לדוגמא האזנה לתקשורת בין רכיבי מחשוב של מערכת שלא בדרך קונבנציונלית (לדוגמא באמצעות שדה מגנטי בכבלים) ואו נגישות לנתונים של הארגון אשר עוברים בתווך בינ"ל | F18: גישה פיזית, גישה בתווך | G18: 1 | H18: 1 | J18: 17 | K18: =IFERROR(__xludf.DUMMYFUNCTION("GOOGLETRANSLATE(B19, ""auto"", ""en"")"),"The threat of an access / interception / modification HTTP cookies") -> The threat of an access / interception / modification HTTP cookies | L18: =IFERROR(__xludf.DUMMYFUNCTION("GOOGLETRANSLATE(D19, ""auto"", ""en"")"),"The threat is the possibility of the perpetrator of unauthorized access to protected information (user accounts, certificates, etc.) contained in the cookies-files during storage or transmission, in read mode (the disclosure of privacy) or write (amendmen"&"ts to implementation of threat spoofing a trusted user). This threat is caused by weakness protection cookies-file action: the absence of verification of input data from a network service that uses cookies-files, as well as the lack of encryption when se"&"nding cookies-files. Implementation of this threat is possible under the conditions of a successful intruder unauthorized access to cookies-files and check the integrity of the absence of their values ​​from the application diskreditiruemogo") -> The threat is the possibility of the perpetrator of unauthorized access to protected information (user accounts, certificates, etc.) contained in the cookies-files during storage or transmission, in read mode (the disclosure of privacy) or write (amendments to implementation of threat spoofing a trusted user). This threat is caused by weakness protection cookies-file action: the absence of verification of input data from a network service that uses cookies-files, as well as the lack of encryption when sending cookies-files. Implementation of this threat is possible under the conditions of a successful intruder unauthorized access to cookies-files and check the integrity of the absence of their values ​​from the application diskreditiruemogo | M18: =IFERROR(__xludf.DUMMYFUNCTION("GOOGLETRANSLATE(F19, ""auto"", ""en"")"),"External intruder with a low potential") -> External intruder with a low potential | N18: =IFERROR(__xludf.DUMMYFUNCTION("GOOGLETRANSLATE(H19, ""auto"", ""en"")"),"Application software, network software") -> Application software, network software
B19: בקרת גישה | C19: שטח למטה (סקאדה) | D19: איום פנימי | E19: הרכשה ושימוש בערוץ התקשורת מול הציוד בשטח | F19: גישה פיזית, גישה מול | G19: 1 | H19: 1 | J19: 18 | K19: =IFERROR(__xludf.DUMMYFUNCTION("GOOGLETRANSLATE(B20, ""auto"", ""en"")"),"Download Threat abnormal operating system") -> Download Threat abnormal operating system | L19: =IFERROR(__xludf.DUMMYFUNCTION("GOOGLETRANSLATE(D20, ""auto"", ""en"")"),"The threat is the possibility of substitution of the violator a bootable operating system by unauthorized reconfiguration in the BIOS / UEFI access path to boot the operating system. This threat is caused by weaknesses technologies restricting access to "&"the BIOS / UEFI management. Implementation of this threat can be provided access to the offender the next parameter BIOS / UEFI settings - indication of the operating system boot source") -> The threat is the possibility of substitution of the violator a bootable operating system by unauthorized reconfiguration in the BIOS / UEFI access path to boot the operating system. This threat is caused by weaknesses technologies restricting access to the BIOS / UEFI management. Implementation of this threat can be provided access to the offender the next parameter BIOS / UEFI settings - indication of the operating system boot source | M19: =IFERROR(__xludf.DUMMYFUNCTION("GOOGLETRANSLATE(F20, ""auto"", ""en"")"),"Insider with a low potential") -> Insider with a low potential | N19: =IFERROR(__xludf.DUMMYFUNCTION("GOOGLETRANSLATE(H20, ""auto"", ""en"")"),"BIOS / UEFI firmware") -> BIOS / UEFI firmware
B20: מניעת קוד זדוני | C20: קשר של הארגון עם גורמים חיצוניים | D20: איום חיצוני/שרשרת אספקה | E20: הטמנת קוד עוין בקבצים המועברים מהחברה לארגון - דרך המחשב של החברה ואו באתר אחסון המסמכים | F20: גישה פיזית, גישה באתר | G20: 2 | H20: 2 | J20: 19 | K20: =IFERROR(__xludf.DUMMYFUNCTION("GOOGLETRANSLATE(B21, ""auto"", ""en"")"),"The threat of DNS-cache infection") -> The threat of DNS-cache infection | L20: =IFERROR(__xludf.DUMMYFUNCTION("GOOGLETRANSLATE(D21, ""auto"", ""en"")"),"The threat is the ability to redirect network traffic violator through its own network node mediated by changes in the relevant tables IP- and domain names that are stored in the DNS-server, at the expense of generating an avalanche of possible responses "&"to the request DNS-server a valid user, or by exploiting the DNS-server vulnerabilities . This threat is caused by weakness of mechanisms authentication networking subjects, as well as DNS-server vulnerabilities that can directly replace the DNS-cache DN"&"S-server. Implementation of this threat is possible in the case of the offender privileges sufficient to send network requests to the DNS-server") -> The threat is the ability to redirect network traffic violator through its own network node mediated by changes in the relevant tables IP- and domain names that are stored in the DNS-server, at the expense of generating an avalanche of possible responses to the request DNS-server a valid user, or by exploiting the DNS-server vulnerabilities . This threat is caused by weakness of mechanisms authentication networking subjects, as well as DNS-server vulnerabilities that can directly replace the DNS-cache DNS-server. Implementation of this threat is possible in the case of the offender privileges sufficient to send network requests to the DNS-server | M20: =IFERROR(__xludf.DUMMYFUNCTION("GOOGLETRANSLATE(F21, ""auto"", ""en"")"),"External intruder with a low potential") -> External intruder with a low potential | N20: =IFERROR(__xludf.DUMMYFUNCTION("GOOGLETRANSLATE(H21, ""auto"", ""en"")"),"Network node, network software, network traffic") -> Network node, network software, network traffic
B21: בקרת גישה | C21: ניצול הרשאות עובד פנימי/חיצוני | D21: איום פנימי/חיצוני | E21: גיוס/ניצול בעל תפקיד עם הרשאות גבוהות, יכולת השפעה על המערכות/תהליכים, גישה מורשית רחבה למידע ואו נגישות פיזית למתחמים מסווגים והשבתתן/שיבושן תוך ביצוע נזק פיזי/לוגי ופרסום הנזק | F21: גישת הרשאות, גישה רשתית | G21: 1 | H21: 2 | J21: 20 | K21: =IFERROR(__xludf.DUMMYFUNCTION("GOOGLETRANSLATE(B22, ""auto"", ""en"")"),"The threat of abuse the opportunities offered by cloud-based services to consumers") -> The threat of abuse the opportunities offered by cloud-based services to consumers | L21: =IFERROR(__xludf.DUMMYFUNCTION("GOOGLETRANSLATE(D22, ""auto"", ""en"")"),"The threat is the possibility of the consumer of cloud services (the offender) spam, unauthorized access to the virtual machines to other consumers of cloud services or other destructive software effects on different systems using leased resources of the "&"cloud server. This threat stems from the fact that the cloud service consumer can install their own software on the cloud server. Implementation of this threat is possible by installing and running the consumer cloud services malicious software on the c"&"loud server. Successful implementation of this threat the consumer of cloud services has a negative effect on the reputation of the supplier of cloud services") -> The threat is the possibility of the consumer of cloud services (the offender) spam, unauthorized access to the virtual machines to other consumers of cloud services or other destructive software effects on different systems using leased resources of the cloud server. This threat stems from the fact that the cloud service consumer can install their own software on the cloud server. Implementation of this threat is possible by installing and running the consumer cloud services malicious software on the cloud server. Successful implementation of this threat the consumer of cloud services has a negative effect on the reputation of the supplier of cloud services | M21: =IFERROR(__xludf.DUMMYFUNCTION("GOOGLETRANSLATE(F22, ""auto"", ""en"")"),"Insider with a low potential") -> Insider with a low potential | N21: =IFERROR(__xludf.DUMMYFUNCTION("GOOGLETRANSLATE(H22, ""auto"", ""en"")"),"Cloud system, the virtual machine") -> Cloud system, the virtual machine
B22: בקרת גישה | C22: ניצול הרשאות עובד פנימי/חיצוני | D22: איום פנימי/חיצוני | E22: גיוס/ניצול בעל תפקיד עם הרשאות משתמש וניסיון לבצע העלאת הרשאות, החדרת כלי תקיפה ע"י התוקף במחשב של המשתמש (ביקורת, ספק, עובד חיצוני וכדומה) והמחובר למערכות הארגון | F22: גישת הרשאות, גישה רשתית | G22: 2 | H22: 3 | J22: 21 | K22: =IFERROR(__xludf.DUMMYFUNCTION("GOOGLETRANSLATE(B23, ""auto"", ""en"")"),"The threat of abuse of trust cloud services consumers") -> The threat of abuse of trust cloud services consumers | L22: =IFERROR(__xludf.DUMMYFUNCTION("GOOGLETRANSLATE(D23, ""auto"", ""en"")"),"The threat is the possibility of a violation (accidentally or intentionally) security of information consumers of cloud services insiders provider of cloud services. This threat stems from the fact that a significant part of the security functions transf"&"erred to the responsibility of the provider of cloud services, as well as the impossibility of acceptance by the consumer of cloud services protection against the actions of the provider of cloud services. Implementation of this threat is possible provid"&"ed that consumers of cloud services is not part of the organization engaged in the provision of these cloud-based services (ie the consumer actually transferred to the supplier's own information for its processing)") -> The threat is the possibility of a violation (accidentally or intentionally) security of information consumers of cloud services insiders provider of cloud services. This threat stems from the fact that a significant part of the security functions transferred to the responsibility of the provider of cloud services, as well as the impossibility of acceptance by the consumer of cloud services protection against the actions of the provider of cloud services. Implementation of this threat is possible provided that consumers of cloud services is not part of the organization engaged in the provision of these cloud-based services (ie the consumer actually transferred to the supplier's own information for its processing) | M22: =IFERROR(__xludf.DUMMYFUNCTION("GOOGLETRANSLATE(F23, ""auto"", ""en"")"),"External intruder with a low potential") -> External intruder with a low potential | N22: =IFERROR(__xludf.DUMMYFUNCTION("GOOGLETRANSLATE(H23, ""auto"", ""en"")"),"cloud system") -> cloud system
B23: בקרת גישה | C23: ניצול הרשאות עובד פנימי/חיצוני | D23: איום פנימי/חיצוני | E23: גיוס/ניצול בעל תפקיד עם הרשאות משתמש ושימוש בחשבון של המשתמש כדי ליצור חשבונות נוספים ולהשתמש בחשבונות הללו לצורכי תקיפה תוך טשטוש יכולת הזיהוי של המתקפה בזמן אמת ואו באמצעות נתיב הביקורת | F23: גישת הרשאות, גישה רשתית | G23: 1 | H23: 2 | J23: 22 | K23: =IFERROR(__xludf.DUMMYFUNCTION("GOOGLETRANSLATE(B24, ""auto"", ""en"")"),"The threat of excess allocation of RAM") -> The threat of excess allocation of RAM | L23: =IFERROR(__xludf.DUMMYFUNCTION("GOOGLETRANSLATE(D24, ""auto"", ""en"")"),"The threat is the possibility of substantial resources of RAM to serve the malware requests and a corresponding decrease in the volume of RAM resources available in the system for allocation in response to legitimate users Program requests. This threat i"&"s caused by the presence of the weaknesses of the control mechanism for the allocation of memory to different programs. Implementation of this threat can be subject to a finding of malicious software in the active system") -> The threat is the possibility of substantial resources of RAM to serve the malware requests and a corresponding decrease in the volume of RAM resources available in the system for allocation in response to legitimate users Program requests. This threat is caused by the presence of the weaknesses of the control mechanism for the allocation of memory to different programs. Implementation of this threat can be subject to a finding of malicious software in the active system | M23: =IFERROR(__xludf.DUMMYFUNCTION("GOOGLETRANSLATE(F24, ""auto"", ""en"")"),"External intruder low potential insider with a low potential") -> External intruder low potential insider with a low potential | N23: =IFERROR(__xludf.DUMMYFUNCTION("GOOGLETRANSLATE(H24, ""auto"", ""en"")"),"Hardware, system software, network software") -> Hardware, system software, network software
B24: מניעת קוד זדוני | C24: הנדסה חברתית לעובד פנימי/חיצוני | D24: איום פנימי/חיצוני | E24: הדבקת מחשב של עובד באמצעים גלישה, לדוגמא: א. קוד עוין ברשת אשר יורד ישירות מהאתר ב. החדרת קוד עוין על גבי תעבורת הגלישה ג. החדרת קוד עוין על גבי תשתית החזרת נתוני שאילתה אפליקטיבית ד. חדירה באמצעות קוד עוין המקושר אל הרשת החברתית והדבקת התחנה כאשר מתבצעת פניה מתחנת העבודה לקישור | F24: גישה פיזית, גישה רשתית, גישה מרחוק | G24: 3 | H24: 3 | J24: 23 | K24: =IFERROR(__xludf.DUMMYFUNCTION("GOOGLETRANSLATE(B25, ""auto"", ""en"")"),"Threat of change components of information (automated) systems") -> Threat of change components of information (automated) systems | L24: =IFERROR(__xludf.DUMMYFUNCTION("GOOGLETRANSLATE(D25, ""auto"", ""en"")"),"The threat is the possibility of obtaining the offender access to network files, bookmarks and so on implementation by changing the composition unauthorized software or hardware information system, that further allow to carry out this intruder (or another"&" - external, to detect unauthorized access to the system channel) unauthorized actions in the system. This threat is due to the weaknesses of controls over the integrity of the hardware configuration of the information system. Implementation of this thr"&"eat can be subject to the successful receipt of the infringer necessary powers in the system and the possibility of connection of additional peripheral equipment") -> The threat is the possibility of obtaining the offender access to network files, bookmarks and so on implementation by changing the composition unauthorized software or hardware information system, that further allow to carry out this intruder (or another - external, to detect unauthorized access to the system channel) unauthorized actions in the system. This threat is due to the weaknesses of controls over the integrity of the hardware configuration of the information system. Implementation of this threat can be subject to the successful receipt of the infringer necessary powers in the system and the possibility of connection of additional peripheral equipment | M24: =IFERROR(__xludf.DUMMYFUNCTION("GOOGLETRANSLATE(F25, ""auto"", ""en"")"),"Insider with a low potential") -> Insider with a low potential | N24: =IFERROR(__xludf.DUMMYFUNCTION("GOOGLETRANSLATE(H25, ""auto"", ""en"")"),"Information system, server, workstation, virtual machine, system software, application software, hardware,") -> Information system, server, workstation, virtual machine, system software, application software, hardware,
B25: הדרכות | C25: הנדסה חברתית לעובד פנימי/חיצוני | D25: איום חיצוני | E25: הדבקת מחשב של עובד באמצעות מייל, לדוגמא: א. החדרת קוד עוין באמצעות שליחת קוד עוין המצורף להודעה. ב. הכנסת קישור (LINK) נגוע להודעה המפנה לאתר מתחזה והטעיית המשתמש | F25: גישה פיזית, גישה מתחזה | G25: 3 | H25: 3 | J25: 24 | K25: =IFERROR(__xludf.DUMMYFUNCTION("GOOGLETRANSLATE(B26, ""auto"", ""en"")"),"The threat of changing the mode of the computer hardware elements") -> The threat of changing the mode of the computer hardware elements | L25: =IFERROR(__xludf.DUMMYFUNCTION("GOOGLETRANSLATE(D26, ""auto"", ""en"")"),"The threat is the possibility of changing offender modes of hardware elements by computer BIOS / UEFI unauthorized reconfiguration that allows you to: by changing the frequency of the system bus data transmission mode of communication channels, etc. affe"&"ct the overall performance of your computer or cause malfunctions; due to the lowering of the input voltage, shutdown cooling system temporarily inoperable secure computer; due to the reference invalid operation device parameters (threshold device off w"&"hen overheated, input voltage, etc.) lead to a physical failure of individual computer hardware elements. This threat is caused by weaknesses technologies restricting access to the BIOS / UEFI management. Implementation of this threat can be provided th"&"at the offender privileges to change the corresponding parameters BIOS / UEFI settings") -> The threat is the possibility of changing offender modes of hardware elements by computer BIOS / UEFI unauthorized reconfiguration that allows you to: by changing the frequency of the system bus data transmission mode of communication channels, etc. affect the overall performance of your computer or cause malfunctions; due to the lowering of the input voltage, shutdown cooling system temporarily inoperable secure computer; due to the reference invalid operation device parameters (threshold device off when overheated, input voltage, etc.) lead to a physical failure of individual computer hardware elements. This threat is caused by weaknesses technologies restricting access to the BIOS / UEFI management. Implementation of this threat can be provided that the offender privileges to change the corresponding parameters BIOS / UEFI settings | M25: =IFERROR(__xludf.DUMMYFUNCTION("GOOGLETRANSLATE(F26, ""auto"", ""en"")"),"Insider with high potential") -> Insider with high potential | N25: =IFERROR(__xludf.DUMMYFUNCTION("GOOGLETRANSLATE(H26, ""auto"", ""en"")"),"Firmware and BIOS / UEFI hardware") -> Firmware and BIOS / UEFI hardware
B26: הגנת תחנות עבודה ושרתים | C26: הנדסה חברתית לעובד פנימי/חיצוני | D26: איום חיצוני | E26: הדבקת מחשב של עובד על ידי חיבור מדיה נתיקה נגועה בקוד עוין | F26: גישה פיזית, גישה נגועה | G26: 3 | H26: 3 | J26: 25 | K26: =IFERROR(__xludf.DUMMYFUNCTION("GOOGLETRANSLATE(B27, ""auto"", ""en"")"),"The threat of systemic change and global variables") -> The threat of systemic change and global variables | L26: =IFERROR(__xludf.DUMMYFUNCTION("GOOGLETRANSLATE(D27, ""auto"", ""en"")"),"The threat is the possibility of the offender mediated destructive effects on some software program or the entire system by changing the software used diskreditiruemymi unified system and global variables. This threat is caused by weaknesses in access co"&"ntrol mechanism for shared memory, and the vulnerabilities of software application modules that implement the external integrity of the control variables. Implementation of this threat is possible under the conditions of the intruder successfully unautho"&"rized access to the system and global variables and their lack of integrity checking values ​​from the application diskreditiruemogo") -> The threat is the possibility of the offender mediated destructive effects on some software program or the entire system by changing the software used diskreditiruemymi unified system and global variables. This threat is caused by weaknesses in access control mechanism for shared memory, and the vulnerabilities of software application modules that implement the external integrity of the control variables. Implementation of this threat is possible under the conditions of the intruder successfully unauthorized access to the system and global variables and their lack of integrity checking values ​​from the application diskreditiruemogo | M26: =IFERROR(__xludf.DUMMYFUNCTION("GOOGLETRANSLATE(F27, ""auto"", ""en"")"),"The inner middle potential violator") -> The inner middle potential violator | N26: =IFERROR(__xludf.DUMMYFUNCTION("GOOGLETRANSLATE(H27, ""auto"", ""en"")"),"System software, application software, networking software") -> System software, application software, networking software
B27: הדרכות | C27: הנדסה חברתית לעובד פנימי/חיצוני | D27: איום פנימי | E27: מסירת מידע ערכי ואו מסווג לגורמים לא מורשים ואו לתוקף, באופן וורבלי ואו באמצעות ניירת פיזית, העלולים לשמש לתקיפת המערכת | F27: גישה פיזית, גישה לשמש | G27: 3 | H27: 3 | J27: 26 | K27: =IFERROR(__xludf.DUMMYFUNCTION("GOOGLETRANSLATE(B28, ""auto"", ""en"")"),"The threat of distortion of XML-schema") -> The threat of distortion of XML-schema | L27: =IFERROR(__xludf.DUMMYFUNCTION("GOOGLETRANSLATE(D28, ""auto"", ""en"")"),"The threat lies in the possibility of changing the violator information processing algorithm applications functioning on the basis of XML-schema, until the application driving condition ""Denial of Service"", by changing the XML-schema exchanged between t"&"he client and server. This threat is caused by weakness of measures to ensure the integrity of transmitted when the client-server interaction data, as well as the weaknesses of the mechanism of interaction of open systems network. Implementation of this"&" threat is possible under the conditions of a successful intruder unauthorized access to the network traffic between the client and the server and there is no integrity checking XML-schema from diskreditiruemogo applications") -> The threat lies in the possibility of changing the violator information processing algorithm applications functioning on the basis of XML-schema, until the application driving condition "Denial of Service", by changing the XML-schema exchanged between the client and server. This threat is caused by weakness of measures to ensure the integrity of transmitted when the client-server interaction data, as well as the weaknesses of the mechanism of interaction of open systems network. Implementation of this threat is possible under the conditions of a successful intruder unauthorized access to the network traffic between the client and the server and there is no integrity checking XML-schema from diskreditiruemogo applications | M27: =IFERROR(__xludf.DUMMYFUNCTION("GOOGLETRANSLATE(F28, ""auto"", ""en"")"),"External intruder with an average potential intruder inner middle potential") -> External intruder with an average potential intruder inner middle potential | N27: =IFERROR(__xludf.DUMMYFUNCTION("GOOGLETRANSLATE(H28, ""auto"", ""en"")"),"Network node, network software, network traffic") -> Network node, network software, network traffic
